Workbook

Sheet Attainments
B2: CO-PO MAPPINGS AVERAGE OF ALL COURSES
B4: COURSE | C4: PO1 | D4: PO2 | E4: PO3 | F4: PO4 | G4: PO5 | H4: PO6 | I4: PO7 | J4: PO8 | K4: PO9 | L4: PO10 | M4: PO11 | N4: PO12 | P4: COURSE | Q4: PO1 | R4: PO2 | S4: PO3 | T4: PO4 | U4: PO5 | V4: PO6 | W4: PO7 | X4: PO8 | Y4: PO9 | Z4: PO10 | AA4: PO11 | AB4: PO12
B5: FIRST YEAR COURSES | P5: SECOND YEAR COURSES
B6: M 1 | C6: ='M-I'!C82 -> 3 | D6: ='M-I'!D82 -> 3 | N6: ='M-I'!N82 -> 3 | P6: M-IV | Q6: ='M-IV'!C88 -> 3 | R6: ='M-IV'!D88 -> 3 | S6: ='M-IV'!E88 -> 1.75 | T6: ='M-IV'!F88 -> 2.25 | U6: ='M-IV'!G88 -> 1 | AB6: ='M-IV'!N88 -> 2
B7: M 2 | C7: ='M-II'!D83 -> 3 | D7: ='M-II'!E83 -> 3 | E7: ='M-II'!F83 -> 1.8 | F7: ='M-II'!G83 -> 2.2 | G7: ='M-II'!H83 -> 1 | N7: ='M-II'!O83 -> 2 | P7: NTA | Q7: =NT!C88 -> 2.75 | R7: =NT!D88 -> 2.75 | S7: =NT!E88 -> 2.5 | T7: =NT!F88 -> 1 | U7: =NT!G88 -> 2 | V7: =NT!H88 -> 1.5 | AB7: =NT!N88 -> 2
B8: PHY | C8: ='PHY '!C80 -> 3 | D8: ='PHY '!D80 -> 3 | E8: ='PHY '!E80 -> 3 | F8: ='PHY '!F80 -> 2.4 | G8: ='PHY '!G80 -> 1.8 | H8: ='PHY '!H80 -> 3 | I8: ='PHY '!I80 -> 2 | J8: ='PHY '!J80 -> 2 | ... N8: ='PHY '!N80 -> 3 | P8: EM | Q8: =EM!C88 -> 2.75 | R8: =EM!D88 -> 2.75 | S8: =EM!E88 -> 2.5 | T8: =EM!F88 -> 1 | U8: =EM!G88 -> 2 | V8: =EM!H88 -> 1.5 | AB8: =EM!N88 -> 2
B9: EG | C9: =EG!B85 -> 2.5 | E9: =EG!D85 -> 2.6666667 | G9: =EG!F85 -> 2 | H9: =EG!G85 -> 2 | L9: =EG!K85 -> 2.25 | N9: =EG!M85 -> 2.25 | P9: EDC | Q9: =EDC!C86 -> 3 | R9: =EDC!D86 -> 3 | S9: =EDC!E86 -> 2.5 | T9: =EDC!F86 -> 1.5 | U9: =EDC!G86 -> 1.75 | V9: =EDC!H86 -> 1 | X9: =EDC!J86 -> 1.5 | AB9: =EDC!N86 -> 2
B10: PHY LAB | C10: =PHYLAB!D73 -> 3 | D10: =PHYLAB!E73 -> 3 | E10: =PHYLAB!F73 -> 1 | F10: =PHYLAB!G73 -> 3 | G10: =PHYLAB!H73 -> 1 | H10: =PHYLAB!I73 -> 3 | I10: =PHYLAB!J73 -> 2 | J10: =PHYLAB!K73 -> 3 | ... N10: =PHYLAB!O73 -> 3 | P10: SS | Q10: =SS!C88 -> 3 | R10: =SS!D88 -> 2 | S10: =SS!E88 -> 2 | T10: =SS!F88 -> 2 | U10: =SS!G88 -> 3 | Y10: =SS!K88 -> 3 | Z10: =SS!L88 -> 2 | AB10: =SS!N88 -> 2
B11: WS LAB | C11: =WSLAB!D72 -> 1 | H11: =WSLAB!I72 -> 2 | K11: =WSLAB!L72 -> 3 | L11: =WSLAB!M72 -> 2 | M11: =WSLAB!N72 -> 3 | N11: =WSLAB!O72 -> 3 | P11: DS | Q11: =DS!C88 -> 3 | R11: =DS!D88 -> 2 | S11: =DS!E88 -> 2 | V11: =DS!H88 -> 1 | AB11: =DS!N88 -> 2
B12: M 3-1.2 | C12: ='M-III1.2'!F81 -> 3 | D12: ='M-III1.2'!G81 -> 2.75 | E12: ='M-III1.2'!H81 -> 1.5 | F12: ='M-III1.2'!I81 -> 2 | N12: ='M-III1.2'!Q81 -> 2 | P12: NTM LAB | Q12: =NTMLAB!C88 -> 3 | R12: =NTMLAB!D88 -> 3 | S12: =NTMLAB!E88 -> 3 | T12: =NTMLAB!F88 -> 2 | U12: =NTMLAB!G88 -> 1 | W12: =NTMLAB!I88 -> 2 | X12: =NTMLAB!J88 -> 2 | Y12: =NTMLAB!K88 -> 3 | Z12: =NTMLAB!L88 -> 3 | AA12: =NTMLAB!M88 -> 1 | AB12: =NTMLAB!N88 -> 3
B13: BEE | C13: =BEE!D83 -> 3 | D13: =BEE!E83 -> 1.6 | E13: =BEE!F83 -> 2.25 | F13: =BEE!G83 -> 2 | G13: =BEE!H83 -> 3 | N13: =BEE!O83 -> 2.4 | P13: EDC LAB | Q13: =EDCLAB!C88 -> 3 | R13: =EDCLAB!D88 -> 2 | S13: =EDCLAB!E88 -> 3 | T13: =EDCLAB!F88 -> 3 | U13: =EDCLAB!G88 -> 3 | V13: =EDCLAB!H88 -> 2 | W13: =EDCLAB!I88 -> 2.75 | AB13: =EDCLAB!N88 -> 2.75
B14: CHE | C14: =CHE!D85 -> 2.6666667 | D14: =CHE!E85 -> 2.1666667 | E14: =CHE!F85 -> 1.1666667 | F14: =CHE!G85 -> 1.8333333 | G14: =CHE!H85 -> 1 | H14: =CHE!I85 -> 1.8333333 | I14: =CHE!J85 -> 2 | J14: =CHE!K85 -> 1.5 | N14: =CHE!O85 -> 2.1666667 | P14: M-V | Q14: ='M-V'!C88 -> 3 | R14: ='M-V'!D88 -> 3 | S14: ='M-V'!E88 -> 1.75 | T14: ='M-V'!F88 -> 2.5 | U14: ='M-V'!G88 -> 1.25 | AB14: ='M-V'!N88 -> 2
B15: CPNM | C15: =CPNM!D81 -> 3 | D15: =CPNM!E81 -> 2.75 | E15: =CPNM!F81 -> 2 | F15: =CPNM!G81 -> 2 | G15: =CPNM!H81 -> 2.5 | K15: =CPNM!L81 -> 1 | L15: =CPNM!M81 -> 1 | M15: =CPNM!N81 -> 1 | N15: =CPNM!O81 -> 2 | P15: EMFTL | Q15: =EMFTL!C88 -> 2.5 | R15: =EMFTL!D88 -> 2.5 | S15: =EMFTL!E88 -> 1 | T15: =EMFTL!F88 -> 1.5 | V15: =EMFTL!H88 -> 1 | AB15: =EMFTL!N88 -> 2
B16: ENG | C16: =ENGLISH1.1!C79 -> 3 | D16: =ENGLISH1.1!D79 -> 2 | E16: =ENGLISH1.1!E79 -> 3 | F16: =ENGLISH1.1!F79 -> 1.4 | G16: =ENGLISH1.1!G79 -> 1 | H16: =ENGLISH1.1!H79 -> 3 | I16: =ENGLISH1.1!I79 -> 3 | J16: =ENGLISH1.1!J79 -> 3 | ... N16: =ENGLISH1.1!N79 -> 3 | P16: AEC | Q16: =AEC!C90 -> 3 | R16: =AEC!D90 -> 3 | S16: =AEC!E90 -> 2 | U16: =AEC!G90 -> 3 | V16: =AEC!H90 -> 2 | W16: =AEC!I90 -> 2 | X16: =AEC!J90 -> 2 | Y16: =AEC!K90 -> 3 | Z16: =AEC!L90 -> 2 | AB16: =AEC!N90 -> 3
B17: CHE LAB | C17: =CHELAB!D73 -> 3 | D17: =CHELAB!E73 -> 3 | E17: =CHELAB!F73 -> 1 | F17: =CHELAB!G73 -> 3 | G17: =CHELAB!H73 -> 1 | H17: =CHELAB!I73 -> 3 | I17: =CHELAB!J73 -> 3 | J17: =CHELAB!K73 -> 3 | ... N17: =CHELAB!O73 -> 3 | P17: STLD | Q17: =STLD!C88 -> 3 | R17: =STLD!D88 -> 2.6666667 | S17: =STLD!E88 -> 2.3333333 | T17: =STLD!F88 -> 2.6666667 | U17: =STLD!G88 -> 2.3333333 | W17: =STLD!I88 -> 3 | Y17: =STLD!K88 -> 3 | AB17: =STLD!N88 -> 2
B18: CPNM LAB | C18: =CPNMLAB!I14 -> 3 | D18: =CPNMLAB!J14 -> 3 | E18: =CPNMLAB!K14 -> 3 | F18: =CPNMLAB!L14 -> 3 | G18: =CPNMLAB!M14 -> 2 | H18: =CPNMLAB!N14 -> 2 | J18: =CPNMLAB!P14 -> 2 | M18: =CPNMLAB!S14 -> 2 | N18: =CPNMLAB!T14 -> 2 | P18: PTRP | Q18: =PTRP!C88 -> 2.75 | R18: =PTRP!D88 -> 2.75 | S18: =PTRP!E88 -> 2.5 | T18: =PTRP!F88 -> 1 | U18: =PTRP!G88 -> 2 | V18: =PTRP!H88 -> 1.5 | AB18: =PTRP!N88 -> 2
P19: ES | Q19: =ES!C90 -> 2.6 | R19: =ES!D90 -> 2.6 | S19: =ES!E90 -> 2.6 | T19: =ES!F90 -> 1 | U19: =ES!G90 -> 2.2 | V19: =ES!H90 -> 1.5 | AB19: =ES!N90 -> 1.8
P20: UHV | Q20: =UHV!C90 -> 2.6 | R20: =UHV!D90 -> 2.6 | S20: =UHV!E90 -> 2.6 | T20: =UHV!F90 -> 1 | U20: =UHV!G90 -> 2.2 | V20: =UHV!H90 -> 1.5 | AB20: =UHV!N90 -> 1.8
P21: DIC LAB | Q21: =DICLAB!C88 -> 3 | R21: =DICLAB!D88 -> 2 | S21: =DICLAB!E88 -> 3 | T21: =DICLAB!F88 -> 3 | U21: =DICLAB!G88 -> 3 | V21: =DICLAB!H88 -> 3 | W21: =DICLAB!I88 -> 2.75 | AB21: =DICLAB!N88 -> 2.75
P22: AEC LAB | Q22: =AECLAB!C88 -> 3 | R22: =AECLAB!D88 -> 2 | S22: =AECLAB!E88 -> 1 | T22: =AECLAB!F88 -> 2 | U22: =AECLAB!G88 -> 1 | V22: =AECLAB!H88 -> 2 | W22: =AECLAB!I88 -> 2 | X22: =AECLAB!J88 -> 3 | ... AB22: =AECLAB!N88 -> 2
B25: COURSE | C25: PO1 | D25: PO2 | E25: PO3 | F25: PO4 | G25: PO5 | H25: PO6 | I25: PO7 | J25: PO8 | K25: PO9 | L25: PO10 | M25: PO11 | N25: PO12 | P25: COURSE | Q25: PO1 | R25: PO2 | S25: PO3 | T25: PO4 | U25: PO5 | V25: PO6 | W25: PO7 | X25: PO8 | Y25: PO9 | Z25: PO10 | AA25: PO11 | AB25: PO12
B26: THIRD YEAR COURSES | P26: FOURTH YEAR COURSES
B27: LICA-3.1 | C27: =LICA3.1!C90 -> 3 | D27: =LICA3.1!D90 -> 2 | E27: =LICA3.1!E90 -> 1.5 | F27: =LICA3.1!F90 -> 2 | G27: =LICA3.1!G90 -> 3 | H27: =LICA3.1!H90 -> 2 | I27: =LICA3.1!I90 -> 2.75 | J27: =LICA3.1!J90 -> 2.3333333 | ... N27: =LICA3.1!N90 -> 2.25 | P27: PEM | Q27: =PEM!C90 -> 1.4 | R27: =PEM!D90 -> 2.4 | S27: =PEM!E90 -> 1.8 | T27: =PEM!F90 -> 1.2 | V27: =PEM!H90 -> 1.6 | W27: =PEM!I90 -> 1.2 | X27: =PEM!J90 -> 2 | Y27: =PEM!K90 -> 1.6666667 | Z27: =PEM!L90 -> 1.6666667 | AA27: =PEM!M90 -> 3 | AB27: =PEM!N90 -> 2.2
B28: AC&DC | C28: ='AC&DC'!D93 -> 3 | D28: ='AC&DC'!E93 -> 3 | E28: ='AC&DC'!F93 -> 2 | G28: ='AC&DC'!H93 -> 3 | H28: ='AC&DC'!I93 -> 2 | I28: ='AC&DC'!J93 -> 2 | J28: ='AC&DC'!K93 -> 2 | K28: ='AC&DC'!L93 -> 3 | L28: ='AC&DC'!M93 -> 2 | N28: ='AC&DC'!O93 -> 3 | P28: RE | Q28: =RE!C90 -> 2 | R28: =RE!D90 -> 3 | S28: =RE!E90 -> 2 | T28: =RE!F90 -> 2 | V28: =RE!H90 -> 2 | AB28: =RE!N90 -> 1
B29: CNE(PE-1) | C29: =CNE!C61 -> 3 | D29: =CNE!D61 -> 2.75 | E29: =CNE!E61 -> 2.5 | F29: =CNE!F61 -> 2 | G29: =CNE!G61 -> 1 | H29: =CNE!H61 -> 2 | J29: =CNE!J61 -> 3 | N29: =CNE!N61 -> 2 | P29: FOC | Q29: =FOC!C54 -> 2.5 | R29: =FOC!D54 -> 2.75 | S29: =FOC!E54 -> 2.75 | T29: =FOC!F54 -> 1 | U29: =FOC!G54 -> 2.25 | W29: =FOC!I54 -> 2
B30: AWP | C30: =AWP!C90 -> 3 | D30: =AWP!D90 -> 2.8 | E30: =AWP!E90 -> 2.5 | F30: =AWP!F90 -> 2.5 | G30: =AWP!G90 -> 2.6 | H30: =AWP!H90 -> 2 | N30: =AWP!N90 -> 3 | P30: IOT | Q30: ='IOT1'!C66 -> 3 | R30: ='IOT1'!D66 -> 2.6 | S30: ='IOT1'!E66 -> 2.2 | T30: ='IOT1'!F66 -> 2.25 | U30: ='IOT1'!G66 -> 3 | W30: ='IOT1'!I66 -> 2.4 | Y30: ='IOT1'!K66 -> 3 | Z30: ='IOT1'!L66 -> 2.25 | AB30: ='IOT1'!N66 -> 2.25
B31: CS | C31: =CS!C88 -> 2.75 | D31: =CS!D88 -> 2.75 | E31: =CS!E88 -> 2.5 | F31: =CS!F88 -> 1 | G31: =CS!G88 -> 2 | H31: =CS!H88 -> 1.5 | N31: =CS!N88 -> 2 | P31: MWE | Q31: =MWE!C90 -> 3 | R31: =MWE!D90 -> 2.6 | S31: =MWE!E90 -> 2.2 | T31: =MWE!F90 -> 3 | U31: =MWE!G90 -> 1.6666667 | Y31: =MWE!K90 -> 3 | AB31: =MWE!N90 -> 3
B32: PDC | C32: =PDC!C90 -> 2.5 | D32: =PDC!D90 -> 2.8 | E32: =PDC!E90 -> 2.5 | F32: =PDC!F90 -> 3 | G32: =PDC!G90 -> 3 | H32: =PDC!H90 -> 2 | N32: =PDC!N90 -> 2 | P32: EMB.SYS | Q32: =EMBEDDEDSYS!C54 -> 2.2 | R32: =EMBEDDEDSYS!D54 -> 2.2 | S32: =EMBEDDEDSYS!E54 -> 2.4 | T32: =EMBEDDEDSYS!F54 -> 2.5 | U32: =EMBEDDEDSYS!G54 -> 3 | V32: =EMBEDDEDSYS!H54 -> 3 | Y32: =EMBEDDEDSYS!K54 -> 3 | AA32: =EMBEDDEDSYS!M54 -> 2 | AB32: =EMBEDDEDSYS!N54 -> 3
B33: MOOCs-1 | C33: ='MOOCs-1'!C88 -> 2.75 | D33: ='MOOCs-1'!D88 -> 2.75 | E33: ='MOOCs-1'!E88 -> 2.5 | F33: ='MOOCs-1'!F88 -> 1 | G33: ='MOOCs-1'!G88 -> 2 | H33: ='MOOCs-1'!H88 -> 1.5 | N33: ='MOOCs-1'!N88 -> 2 | P33: GPS | Q33: =GPS!C68 -> 3 | R33: =GPS!D68 -> 3 | S33: =GPS!E68 -> 1.6 | T33: =GPS!F68 -> 2.6 | U33: =GPS!G68 -> 2.5 | V33: =GPS!H68 -> 3 | W33: =GPS!I68 -> 2.8 | X33: =GPS!J68 -> 2 | ... AB33: =GPS!N68 -> 2.4
B34: LIC LAB | C34: =LICLAB!C88 -> 3 | D34: =LICLAB!D88 -> 2 | E34: =LICLAB!E88 -> 1.5 | F34: =LICLAB!F88 -> 2 | G34: =LICLAB!G88 -> 3 | H34: =LICLAB!H88 -> 2 | I34: =LICLAB!I88 -> 2.75 | J34: =LICLAB!J88 -> 2.3333333 | ... N34: =LICLAB!N88 -> 2.25 | P34: MWELAB | Q34: =MWELAB!C87 -> 3 | R34: =MWELAB!D87 -> 2 | S34: =MWELAB!E87 -> 1 | T34: =MWELAB!F87 -> 2 | U34: =MWELAB!G87 -> 2 | X34: =MWELAB!J87 -> 2 | Y34: =MWELAB!K87 -> 3 | Z34: =MWELAB!L87 -> 3 | AA34: =MWELAB!M87 -> 2 | AB34: =MWELAB!N87 -> 3
B35: ACDC LAB | C35: ='ACDC-LAB'!C88 -> 3 | D35: ='ACDC-LAB'!D88 -> 2 | E35: ='ACDC-LAB'!E88 -> 1 | F35: ='ACDC-LAB'!F88 -> 2 | G35: ='ACDC-LAB'!G88 -> 1 | H35: ='ACDC-LAB'!H88 -> 2 | I35: ='ACDC-LAB'!I88 -> 2 | J35: ='ACDC-LAB'!J88 -> 3 | ... N35: ='ACDC-LAB'!N88 -> 2 | P35: IOP LAB | Q35: ='SKILL LAB'!C88 -> 3 | R35: ='SKILL LAB'!D88 -> 2.5 | S35: ='SKILL LAB'!E88 -> 2.25 | T35: ='SKILL LAB'!F88 -> 2.6666667 | U35: ='SKILL LAB'!G88 -> 3 | W35: ='SKILL LAB'!I88 -> 2.5 | Y35: ='SKILL LAB'!K88 -> 3 | Z35: ='SKILL LAB'!L88 -> 2 | AA35: ='SKILL LAB'!M88 -> 1 | AB35: ='SKILL LAB'!N88 -> 2
B36: VLSI-3.2 | C36: =VLSI3.2!C90 -> 2.8 | D36: =VLSI3.2!D90 -> 2.75 | E36: =VLSI3.2!E90 -> 2.5 | F36: =VLSI3.2!F90 -> 1 | G36: =VLSI3.2!G90 -> 2 | H36: =VLSI3.2!H90 -> 1.5 | N36: =VLSI3.2!N90 -> 2 | P36: INTERNSHIP | Q36: =INTERNSHIP!C88 -> 2 | R36: =INTERNSHIP!D88 -> 2.25 | S36: =INTERNSHIP!E88 -> 1.5 | T36: =INTERNSHIP!F88 -> 2 | U36: =INTERNSHIP!G88 -> 2.25 | V36: =INTERNSHIP!H88 -> 1.75 | W36: =INTERNSHIP!I88 -> 1 | X36: =INTERNSHIP!J88 -> 1.5 | ... AB36: =INTERNSHIP!N88 -> 2.25
B37: MPMC | C37: =MPMC!C90 -> 2.5 | D37: =MPMC!D90 -> 2 | E37: =MPMC!E90 -> 1.75 | F37: =MPMC!F90 -> 2.6666667 | G37: =MPMC!G90 -> 3 | I37: =MPMC!I90 -> 2 | K37: =MPMC!K90 -> 3 | M37: =MPMC!M90 -> 3 | N37: =MPMC!N90 -> 2.5 | P37: PROJECT | Q37: =PROJECT4.2!C88 -> 2.75 | R37: =PROJECT4.2!D88 -> 2.75 | S37: =PROJECT4.2!E88 -> 2.5 | T37: =PROJECT4.2!F88 -> 2.5 | U37: =PROJECT4.2!G88 -> 2.5 | V37: =PROJECT4.2!H88 -> 1 | W37: =PROJECT4.2!I88 -> 1 | Y37: =PROJECT4.2!K88 -> 1.75 | Z37: =PROJECT4.2!L88 -> 2.25 | AA37: =PROJECT4.2!M88 -> 2.3333333 | AB37: =PROJECT4.2!N88 -> 2.25
B38: DSP | C38: =DSP!C90 -> 3 | D38: =DSP!D90 -> 2.75 | E38: =DSP!E90 -> 3 | F38: =DSP!F90 -> 1 | G38: =DSP!G90 -> 2.75 | H38: =DSP!H90 -> 2 | N38: =DSP!N90 -> 2 | P38: MOOCs-2 | Q38: ='MOOCs-II'!C88 -> 3 | R38: ='MOOCs-II'!D88 -> 2.5 | S38: ='MOOCs-II'!E88 -> 2.25 | T38: ='MOOCs-II'!F88 -> 2.6666667 | U38: ='MOOCs-II'!G88 -> 3 | W38: ='MOOCs-II'!I88 -> 2.5 | Y38: ='MOOCs-II'!K88 -> 3 | Z38: ='MOOCs-II'!L88 -> 2 | AA38: ='MOOCs-II'!M88 -> 1 | AB38: ='MOOCs-II'!N88 -> 2
B39: CMC | C39: =CMC!C63 -> 3 | D39: =CMC!D63 -> 2 | E39: =CMC!E63 -> 2 | F39: =CMC!F63 -> 2 | G39: =CMC!G63 -> 3 | I39: =CMC!I63 -> 2 | K39: =CMC!K63 -> 3 | L39: =CMC!L63 -> 3 | N39: =CMC!N63 -> 3
B40: ITC | C40: =ITC!C61 -> 3 | D40: =ITC!D61 -> 1.8 | E40: =ITC!E61 -> 1.4 | F40: =ITC!F61 -> 2.2 | G40: =ITC!G61 -> 3 | I40: =ITC!I61 -> 2 | N40: =ITC!N61 -> 2
B41: SC | C41: =SC!C55 -> 3 | D41: =SC!D55 -> 3 | E41: =SC!E55 -> 1.75 | F41: =SC!F55 -> 3 | G41: =SC!G55 -> 3 | I41: =SC!I55 -> 2.5 | J41: =SC!J55 -> 2 | K41: =SC!K55 -> 3 | L41: =SC!L55 -> 3 | M41: =SC!M55 -> 2 | N41: =SC!N55 -> 3
B42: EMI | C42: =EMI!C60 -> 2.75 | D42: =EMI!D60 -> 2.75 | E42: =EMI!E60 -> 2.5 | F42: =EMI!F60 -> 1 | G42: =EMI!G60 -> 2 | H42: =EMI!H60 -> 1.5 | N42: =EMI!N60 -> 2
B43: DSP LAB | C43: =DSPLAB!C87 -> 3 | D43: =DSPLAB!D87 -> 2.5 | E43: =DSPLAB!E87 -> 2 | F43: =DSPLAB!F87 -> 2.6666667 | G43: =DSPLAB!G87 -> 3 | I43: =DSPLAB!I87 -> 2 | J43: =DSPLAB!J87 -> 2 | K43: =DSPLAB!K87 -> 3 | L43: =DSPLAB!L87 -> 3 | M43: =DSPLAB!M87 -> 3 | N43: =DSPLAB!N87 -> 2.5
B44: MPMC LAB | C44: =MPMCLAB!C87 -> 3 | D44: =MPMCLAB!D87 -> 2.5 | E44: =MPMCLAB!E87 -> 2.5 | F44: =MPMCLAB!F87 -> 2.5 | G44: =MPMCLAB!G87 -> 3 | I44: =MPMCLAB!I87 -> 2 | J44: =MPMCLAB!J87 -> 2 | K44: =MPMCLAB!K87 -> 3 | L44: =MPMCLAB!L87 -> 3 | M44: =MPMCLAB!M87 -> 3 | N44: =MPMCLAB!N87 -> 2.75
...

Sheet M-I
A2: Subject: | C2: Mathematics - I | I2: AY: | K2: 2019-20
A3: Faculty: | C3: Dr. K.V.S.SARMA | I3: Batch: | K3: 2019-2023
B4: Year and Semester: | C4: I Yr I Semester | I4: Branch: | K4: ECE
C5: I Mid | N5: II MID
B6: Register Number | C6: Question No.1 | H6: Question No 2 | J6: Question No 3 | L6: Question No 4 | N6: Question No.1 | S6: Question No 2 | U6: Question No 3 | W6: Question No 4 | Y6: University Grade | Z6: Marks Obtained
C7: a | D7: b | E7: c | F7: d | G7: e | H7: a | I7: b | J7: a | K7: b | L7: a | M7: b | N7: a | O7: b | P7: c | Q7: a | R7: b | S7: a | T7: b | U7: a | V7: b | W7: a | X7: b
B8: Matching CO | C8: CO1 | D8: CO1 | E8: CO2 | F8: CO1 | G8: CO1 | H8: CO1 | I8: CO1 | J8: CO2 | K8: CO2 | L8: CO2 | M8: CO2 | N8: CO3 | O8: CO4 | P8: CO5 | Q8: CO3 | R8: CO3 | S8: CO4 | T8: CO4 | U8: CO5 | V8: CO5 | W8: CO5 | X8: CO5
A9: Sl.No. | B9: Maximum Marks | C9: 2 | D9: 2 | E9: 2 | F9: 2 | G9: 2 | H9: 5 | I9: 5 | J9: 5 | K9: 5 | L9: 5 | M9: 5 | N9: 2 | O9: 2 | P9: 2 | Q9: 2 | R9: 2 | S9: 5 | T9: 5 | U9: 5 | V9: 5 | W9: 5 | X9: 5 | Y9: 100
A10: 1 | B10: 5191421001 | C10: 1 | E10: 1 | F10: 1 | H10: 5 | I10: 2 | L10: 5 | M10: 5 | N10: 1 | P10: 2 | Q10: 2 | S10: 4 | W10: 5 | X10: 4 | Y10: B+ | Z10: =IF(Y10="O",100,IF(Y10="A+",90,IF(Y10="A",80,IF(Y10="B+",70,IF(Y10="B",60,IF(Y10="C",55,IF(Y10="P",50,IF(Y10="F",39)))))))) -> 70
A11: 2 | B11: =+B10+1 -> 5191421002 | D11: 2 | E11: 2 | F11: 2 | G11: 2 | H11: 5 | I11: 3 | L11: 5 | M11: 5 | O11: 2 | P11: 2 | Q11: 2 | U11: 4 | V11: 5 | W11: 5 | X11: 3 | Y11: A+ | Z11: =IF(Y11="O",100,IF(Y11="A+",90,IF(Y11="A",80,IF(Y11="B+",70,IF(Y11="B",60,IF(Y11="C",55,IF(Y11="P",50,IF(Y11="F",39)))))))) -> 90
A12: 3 | B12: =+B11+1 -> 5191421003 | C12: 1 | D12: 1 | E12: 2 | F12: 2 | G12: 2 | H12: 5 | I12: 5 | J12: 5 | K12: 5 | L12: 5 | M12: 5 | N12: 1 | O12: 2 | P12: 2 | Q12: 2 | S12: 5 | T12: 5 | U12: 5 | V12: 5 | Y12: O | Z12: =IF(Y12="O",100,IF(Y12="A+",90,IF(Y12="A",80,IF(Y12="B+",70,IF(Y12="B",60,IF(Y12="C",55,IF(Y12="P",50,IF(Y12="F",39)))))))) -> 100
A13: 4 | B13: =+B12+1 -> 5191421004 | C13: 1 | D13: 1 | E13: 2 | G13: 2 | H13: 3 | I13: 1 | N13: 2 | O13: 1 | P13: 2 | R13: 2 | T13: 5 | V13: 4 | Y13: F | Z13: =IF(Y13="O",100,IF(Y13="A+",90,IF(Y13="A",80,IF(Y13="B+",70,IF(Y13="B",60,IF(Y13="C",55,IF(Y13="P",50,IF(Y13="F",39)))))))) -> 39
A14: 5 | B14: =+B13+1 -> 5191421005 | C14: 1 | E14: 2 | G14: 2 | H14: 5 | J14: 5 | N14: 2 | O14: 2 | P14: 2 | S14: 5 | T14: 2 | U14: 5 | V14: 4 | Y14: B+ | Z14: =IF(Y14="O",100,IF(Y14="A+",90,IF(Y14="A",80,IF(Y14="B+",70,IF(Y14="B",60,IF(Y14="C",55,IF(Y14="P",50,IF(Y14="F",39)))))))) -> 70
A15: 6 | B15: =+B14+1 -> 5191421006 | C15: 1 | D15: 1 | E15: 2 | F15: 2 | G15: 2 | H15: 5 | I15: 5 | J15: 5 | L15: 5 | M15: 5 | N15: 2 | O15: 2 | P15: 2 | Q15: 2 | R15: 2 | S15: 5 | T15: 5 | U15: 5 | V15: 5 | Y15: O | Z15: =IF(Y15="O",100,IF(Y15="A+",90,IF(Y15="A",80,IF(Y15="B+",70,IF(Y15="B",60,IF(Y15="C",55,IF(Y15="P",50,IF(Y15="F",39)))))))) -> 100
A16: 7 | B16: =+B15+1 -> 5191421007 | C16: 1 | D16: 1 | E16: 2 | F16: 2 | G16: 2 | H16: 5 | I16: 3 | J16: 2 | L16: 5 | M16: 5 | N16: 2 | P16: 2 | Q16: 2 | R16: 1 | S16: 5 | T16: 5 | W16: 5 | X16: 4 | Y16: A+ | Z16: =IF(Y16="O",100,IF(Y16="A+",90,IF(Y16="A",80,IF(Y16="B+",70,IF(Y16="B",60,IF(Y16="C",55,IF(Y16="P",50,IF(Y16="F",39)))))))) -> 90
A17: 8 | B17: =+B16+1 -> 5191421008 | C17: 2 | D17: 1 | E17: 2 | F17: 2 | H17: 2 | J17: 3 | K17: 1 | N17: 2 | P17: 2 | U17: 5 | W17: 3 | X17: 2 | Y17: B | Z17: =IF(Y17="O",100,IF(Y17="A+",90,IF(Y17="A",80,IF(Y17="B+",70,IF(Y17="B",60,IF(Y17="C",55,IF(Y17="P",50,IF(Y17="F",39)))))))) -> 60
A18: 9 | B18: =+B17+1 -> 5191421009 | C18: 1 | D18: 2 | E18: 2 | G18: 1 | H18: 3 | J18: 5 | K18: 1 | L18: 5 | M18: 3 | N18: 2 | O18: 2 | Q18: 2 | S18: 2 | T18: 5 | W18: 5 | X18: 1 | Y18: A | Z18: =IF(Y18="O",100,IF(Y18="A+",90,IF(Y18="A",80,IF(Y18="B+",70,IF(Y18="B",60,IF(Y18="C",55,IF(Y18="P",50,IF(Y18="F",39)))))))) -> 80
A19: 10 | B19: =+B18+1 -> 5191421010 | C19: 1 | D19: 1 | E19: 2 | H19: 2 | J19: 5 | K19: 3 | L19: 5 | O19: 2 | P19: 2 | Q19: 2 | S19: 5 | U19: 2 | W19: 3 | Y19: B+ | Z19: =IF(Y19="O",100,IF(Y19="A+",90,IF(Y19="A",80,IF(Y19="B+",70,IF(Y19="B",60,IF(Y19="C",55,IF(Y19="P",50,IF(Y19="F",39)))))))) -> 70
A20: 11 | B20: =+B19+1 -> 5191421011 | C20: 1 | D20: 2 | E20: 2 | G20: 2 | H20: 5 | J20: 5 | K20: 5 | L20: 5 | M20: 5 | N20: 2 | O20: 2 | P20: 1 | R20: 1 | S20: 4 | W20: 5 | X20: 5 | Y20: A+ | Z20: =IF(Y20="O",100,IF(Y20="A+",90,IF(Y20="A",80,IF(Y20="B+",70,IF(Y20="B",60,IF(Y20="C",55,IF(Y20="P",50,IF(Y20="F",39)))))))) -> 90
A21: 12 | B21: =+B20+1 -> 5191421012 | K21: 1 | M21: 2 | P21: 1 | Q21: 1 | S21: 3 | U21: 5 | X21: 5 | Y21: P | Z21: =IF(Y21="O",100,IF(Y21="A+",90,IF(Y21="A",80,IF(Y21="B+",70,IF(Y21="B",60,IF(Y21="C",55,IF(Y21="P",50,IF(Y21="F",39)))))))) -> 50
A22: 13 | B22: =+B21+1 -> 5191421013 | C22: 1 | D22: 1 | E22: 2 | F22: 1 | H22: 5 | J22: 2 | K22: 3 | N22: 2 | O22: 2 | P22: 2 | Q22: 2 | S22: 5 | T22: 3 | W22: 5 | X22: 5 | Y22: A | Z22: =IF(Y22="O",100,IF(Y22="A+",90,IF(Y22="A",80,IF(Y22="B+",70,IF(Y22="B",60,IF(Y22="C",55,IF(Y22="P",50,IF(Y22="F",39)))))))) -> 80
A23: 14 | B23: =+B22+1 -> 5191421014 | C23: 1 | D23: 2 | E23: 1 | H23: 5 | I23: 1 | J23: 2 | K23: 2 | N23: 2 | O23: 1 | P23: 1 | Q23: 1 | R23: 1 | T23: 5 | W23: 5 | X23: 5 | Y23: A | Z23: =IF(Y23="O",100,IF(Y23="A+",90,IF(Y23="A",80,IF(Y23="B+",70,IF(Y23="B",60,IF(Y23="C",55,IF(Y23="P",50,IF(Y23="F",39)))))))) -> 80
A24: 15 | B24: =+B23+1 -> 5191421015 | C24: 1 | D24: 1 | E24: 1 | F24: 1 | H24: 3 | I24: 2 | L24: 5 | N24: 2 | P24: 2 | U24: 5 | V24: 3 | W24: 5 | Y24: P | Z24: =IF(Y24="O",100,IF(Y24="A+",90,IF(Y24="A",80,IF(Y24="B+",70,IF(Y24="B",60,IF(Y24="C",55,IF(Y24="P",50,IF(Y24="F",39)))))))) -> 50
A25: 16 | B25: =+B24+1 -> 5191421016 | D25: 1 | E25: 1 | F25: 1 | G25: 2 | H25: 2 | J25: 5 | Y25: P | Z25: =IF(Y25="O",100,IF(Y25="A+",90,IF(Y25="A",80,IF(Y25="B+",70,IF(Y25="B",60,IF(Y25="C",55,IF(Y25="P",50,IF(Y25="F",39)))))))) -> 50
A26: 17 | B26: =+B25+1 -> 5191421017 | C26: 1 | D26: 1 | E26: 2 | G26: 2 | H26: 2 | J26: 2 | N26: 2 | S26: 2 | T26: 2 | W26: 1 | X26: 5 | Y26: B | Z26: =IF(Y26="O",100,IF(Y26="A+",90,IF(Y26="A",80,IF(Y26="B+",70,IF(Y26="B",60,IF(Y26="C",55,IF(Y26="P",50,IF(Y26="F",39)))))))) -> 60
A27: 18 | B27: =+B26+1 -> 5191421018 | E27: 2 | X27: 3 | Y27: B | Z27: =IF(Y27="O",100,IF(Y27="A+",90,IF(Y27="A",80,IF(Y27="B+",70,IF(Y27="B",60,IF(Y27="C",55,IF(Y27="P",50,IF(Y27="F",39)))))))) -> 60
A28: 19 | B28: =+B27+1 -> 5191421019 | C28: 2 | D28: 1 | E28: 2 | F28: 2 | G28: 2 | H28: 5 | J28: 5 | K28: 5 | L28: 5 | M28: 3 | N28: 2 | P28: 2 | Q28: 2 | S28: 5 | T28: 5 | U28: 5 | V28: 3 | Y28: O | Z28: =IF(Y28="O",100,IF(Y28="A+",90,IF(Y28="A",80,IF(Y28="B+",70,IF(Y28="B",60,IF(Y28="C",55,IF(Y28="P",50,IF(Y28="F",39)))))))) -> 100
A29: 20 | B29: =+B28+1 -> 5191421020 | C29: 2 | D29: 2 | E29: 2 | F29: 2 | H29: 5 | I29: 5 | J29: 5 | K29: 5 | L29: 5 | M29: 2 | N29: 2 | P29: 2 | Q29: 2 | S29: 5 | T29: 5 | U29: 5 | V29: 3 | Y29: O | Z29: =IF(Y29="O",100,IF(Y29="A+",90,IF(Y29="A",80,IF(Y29="B+",70,IF(Y29="B",60,IF(Y29="C",55,IF(Y29="P",50,IF(Y29="F",39)))))))) -> 100
A30: 21 | B30: =+B29+1 -> 5191421021 | C30: 1 | E30: 2 | F30: 1 | H30: 5 | J30: 5 | K30: 5 | L30: 5 | N30: 2 | O30: 2 | P30: 2 | Q30: 2 | S30: 5 | T30: 2 | U30: 5 | V30: 2 | Y30: A | Z30: =IF(Y30="O",100,IF(Y30="A+",90,IF(Y30="A",80,IF(Y30="B+",70,IF(Y30="B",60,IF(Y30="C",55,IF(Y30="P",50,IF(Y30="F",39)))))))) -> 80
A31: 22 | B31: =+B30+1 -> 5191421022 | C31: 1 | E31: 2 | H31: 3 | N31: 2 | O31: 1 | P31: 2 | T31: 3 | X31: 3 | Y31: B+ | Z31: =IF(Y31="O",100,IF(Y31="A+",90,IF(Y31="A",80,IF(Y31="B+",70,IF(Y31="B",60,IF(Y31="C",55,IF(Y31="P",50,IF(Y31="F",39)))))))) -> 70
A32: 23 | B32: =+B31+1 -> 5191421023 | C32: 1 | E32: 2 | H32: 2 | I32: 1 | N32: 2 | O32: 1 | P32: 2 | Q32: 2 | R32: 1 | W32: 2 | X32: 2 | Y32: P | Z32: =IF(Y32="O",100,IF(Y32="A+",90,IF(Y32="A",80,IF(Y32="B+",70,IF(Y32="B",60,IF(Y32="C",55,IF(Y32="P",50,IF(Y32="F",39)))))))) -> 50
A33: 24 | B33: =+B32+1 -> 5191421024 | E33: 1 | H33: 2 | J33: 5 | K33: 2 | Y33: C | Z33: =IF(Y33="O",100,IF(Y33="A+",90,IF(Y33="A",80,IF(Y33="B+",70,IF(Y33="B",60,IF(Y33="C",55,IF(Y33="P",50,IF(Y33="F",39)))))))) -> 55
A34: 25 | B34: =+B33+1 -> 5191421025 | C34: 2 | D34: 2 | E34: 2 | F34: 2 | G34: 2 | H34: 5 | I34: 5 | J34: 5 | K34: 5 | L34: 5 | M34: 5 | N34: 2 | O34: 2 | P34: 2 | Q34: 2 | R34: 5 | S34: 5 | W34: 5 | X34: 5 | Y34: O | Z34: =IF(Y34="O",100,IF(Y34="A+",90,IF(Y34="A",80,IF(Y34="B+",70,IF(Y34="B",60,IF(Y34="C",55,IF(Y34="P",50,IF(Y34="F",39)))))))) -> 100
A35: 26 | B35: =+B34+1 -> 5191421026 | C35: 1 | D35: 1 | E35: 2 | F35: 2 | H35: 5 | I35: 5 | J35: 4 | K35: 1 | Y35: A | Z35: =IF(Y35="O",100,IF(Y35="A+",90,IF(Y35="A",80,IF(Y35="B+",70,IF(Y35="B",60,IF(Y35="C",55,IF(Y35="P",50,IF(Y35="F",39)))))))) -> 80
A36: 27 | B36: =+B35+1 -> 5191421027 | N36: 2 | O36: 2 | P36: 2 | Q36: 2 | R36: 1 | S36: 5 | T36: 5 | W36: 5 | X36: 5 | Y36: O | Z36: =IF(Y36="O",100,IF(Y36="A+",90,IF(Y36="A",80,IF(Y36="B+",70,IF(Y36="B",60,IF(Y36="C",55,IF(Y36="P",50,IF(Y36="F",39)))))))) -> 100
A37: 28 | B37: =+B36+1 -> 5191421028 | C37: 1 | E37: 2 | F37: 2 | G37: 2 | H37: 5 | I37: 5 | J37: 4 | K37: 5 | L37: 2 | N37: 2 | O37: 2 | P37: 2 | Q37: 2 | S37: 5 | T37: 5 | W37: 5 | X37: 5 | Y37: A+ | Z37: =IF(Y37="O",100,IF(Y37="A+",90,IF(Y37="A",80,IF(Y37="B+",70,IF(Y37="B",60,IF(Y37="C",55,IF(Y37="P",50,IF(Y37="F",39)))))))) -> 90
A38: 29 | B38: =+B37+1 -> 5191421029 | E38: 2 | H38: 2 | J38: 3 | K38: 1 | O38: 1 | S38: 1 | W38: 5 | X38: 5 | Y38: B | Z38: =IF(Y38="O",100,IF(Y38="A+",90,IF(Y38="A",80,IF(Y38="B+",70,IF(Y38="B",60,IF(Y38="C",55,IF(Y38="P",50,IF(Y38="F",39)))))))) -> 60
A39: 30 | B39: =+B38+1 -> 5191421030 | C39: 1 | E39: 1 | H39: 1 | O39: 1 | X39: 2 | Y39: F | Z39: =IF(Y39="O",100,IF(Y39="A+",90,IF(Y39="A",80,IF(Y39="B+",70,IF(Y39="B",60,IF(Y39="C",55,IF(Y39="P",50,IF(Y39="F",39)))))))) -> 39
A40: 31 | B40: =+B39+1 -> 5191421031 | C40: 1 | D40: 1 | E40: 2 | F40: 1 | G40: 2 | H40: 3 | J40: 5 | K40: 1 | L40: 5 | M40: 4 | N40: 2 | O40: 2 | P40: 2 | Q40: 2 | S40: 5 | T40: 5 | W40: 5 | X40: 5 | Y40: A | Z40: =IF(Y40="O",100,IF(Y40="A+",90,IF(Y40="A",80,IF(Y40="B+",70,IF(Y40="B",60,IF(Y40="C",55,IF(Y40="P",50,IF(Y40="F",39)))))))) -> 80
A41: 32 | B41: =+B40+1 -> 5191421032 | C41: 1 | D41: 2 | E41: 1 | G41: 1 | H41: 5 | M41: 1 | N41: 2 | Q41: 1 | S41: 5 | T41: 4 | W41: 4 | X41: 4 | Y41: F | Z41: =IF(Y41="O",100,IF(Y41="A+",90,IF(Y41="A",80,IF(Y41="B+",70,IF(Y41="B",60,IF(Y41="C",55,IF(Y41="P",50,IF(Y41="F",39)))))))) -> 39
...

Sheet M-II
A2: Subject: | C2: Mathematics - II | J2: AY: | L2: 2019-120
A3: Faculty: | C3: Dr. S. RAJESH | J3: Batch: | L3: 2019-2023
A4: Year and Semester: | C4: I Yr I Semester | J4: Branch: | L4: ECE
C5: I Mid | N5: II MID
B6: Register Number | C6: Question No.1 | H6: Question No 2 | J6: Question No 3 | L6: Question No 4 | N6: Question No.1 | S6: Question No 2 | U6: Question No 3 | W6: Question No 4 | Z6: University Grade | AA6: Marks Obtained
C7: a | D7: b | E7: c | F7: d | G7: e | H7: a | I7: b | J7: a | K7: b | L7: a | N7: a | O7: b | P7: c | Q7: d | R7: e | S7: a | T7: b | U7: a | V7: b | W7: a | X7: b
B8: Matching CO | C8: CO1 | D8: CO1 | E8: CO2 | F8: CO1 | G8: CO1 | H8: CO1 | I8: CO1 | J8: CO2 | K8: CO2 | L8: CO2 | N8: CO3 | O8: CO4 | P8: CO5 | Q8: CO3 | R8: CO3 | S8: CO4 | T8: CO4 | U8: CO5 | V8: CO5 | W8: CO5 | X8: CO5
A9: Sl.No. | B9: Maximum Marks | C9: 2 | D9: 2 | E9: 2 | F9: 2 | G9: 2 | H9: 5 | I9: 5 | J9: 5 | K9: 5 | L9: 10 | N9: 2 | O9: 2 | P9: 2 | Q9: 2 | R9: 2 | S9: 5 | T9: 5 | U9: 5 | V9: 5 | W9: 5 | X9: 5 | Z9: 100
A10: 1 | B10: 5191421001 | C10: 2 | D10: 2 | E10: 2 | F10: 2 | G10: 2 | H10: 5 | I10: 5 | L10: 10 | N10: 2 | O10: 0 | P10: 0 | Q10: 2 | R10: 1 | S10: 5 | T10: 5 | U10: 2 | Z10: B | AA10: =IF(Z10="O",100,IF(Z10="A+",90,IF(Z10="A",80,IF(Z10="B+",70,IF(Z10="B",60,IF(Z10="C",55,IF(Z10="P",50,IF(Z10="F",39)))))))) -> 60
A11: 2 | B11: =+B10+1 -> 5191421002 | C11: 2 | D11: 2 | E11: 2 | G11: 1 | H11: 5 | I11: 5 | J11: 5 | K11: 3 | N11: 2 | O11: 2 | P11: 2 | Q11: 2 | R11: 2 | S11: 4 | T11: 5 | U11: 4 | W11: 4 | X11: 2 | Z11: C | AA11: =IF(Z11="O",100,IF(Z11="A+",90,IF(Z11="A",80,IF(Z11="B+",70,IF(Z11="B",60,IF(Z11="C",55,IF(Z11="P",50,IF(Z11="F",39)))))))) -> 55
A12: 3 | B12: =+B11+1 -> 5191421003 | C12: 2 | D12: 2 | E12: 2 | F12: 2 | G12: 2 | H12: 5 | I12: 5 | L12: 10 | N12: 2 | O12: 2 | P12: 2 | Q12: 2 | R12: 2 | S12: 5 | T12: 5 | U12: 5 | V12: 5 | Z12: O | AA12: =IF(Z12="O",100,IF(Z12="A+",90,IF(Z12="A",80,IF(Z12="B+",70,IF(Z12="B",60,IF(Z12="C",55,IF(Z12="P",50,IF(Z12="F",39)))))))) -> 100
A13: 4 | B13: =+B12+1 -> 5191421004 | C13: 1 | D13: 2 | E13: 2 | F13: 2 | G13: 2 | H13: 5 | I13: 3 | J13: 2 | K13: 2 | N13: 2 | O13: 1 | P13: 0 | Q13: 0 | R13: 0 | S13: 2 | T13: 2 | U13: 3 | V13: 2 | Z13: C | AA13: =IF(Z13="O",100,IF(Z13="A+",90,IF(Z13="A",80,IF(Z13="B+",70,IF(Z13="B",60,IF(Z13="C",55,IF(Z13="P",50,IF(Z13="F",39)))))))) -> 55
A14: 5 | B14: =+B13+1 -> 5191421005 | C14: 2 | D14: 2 | E14: 2 | F14: 2 | G14: 2 | H14: 5 | I14: 5 | J14: 4 | K14: 4 | N14: 2 | O14: 2 | P14: 0 | Q14: 0 | R14: 0 | S14: 5 | T14: 3 | U14: 0 | Z14: C | AA14: =IF(Z14="O",100,IF(Z14="A+",90,IF(Z14="A",80,IF(Z14="B+",70,IF(Z14="B",60,IF(Z14="C",55,IF(Z14="P",50,IF(Z14="F",39)))))))) -> 55
A15: 6 | B15: =+B14+1 -> 5191421006 | C15: 2 | D15: 2 | E15: 2 | F15: 2 | G15: 2 | H15: 5 | I15: 5 | J15: 5 | K15: 5 | N15: 2 | O15: 2 | P15: 1 | Q15: 2 | R15: 2 | S15: 5 | T15: 0 | U15: 5 | V15: 5 | W15: 5 | X15: 2 | Z15: A | AA15: =IF(Z15="O",100,IF(Z15="A+",90,IF(Z15="A",80,IF(Z15="B+",70,IF(Z15="B",60,IF(Z15="C",55,IF(Z15="P",50,IF(Z15="F",39)))))))) -> 80
A16: 7 | B16: =+B15+1 -> 5191421007 | C16: 2 | D16: 2 | E16: 2 | F16: 2 | G16: 2 | J16: 5 | K16: 5 | L16: 10 | N16: 2 | O16: 2 | P16: 0 | Q16: 2 | R16: 0 | S16: 5 | T16: 2 | U16: 0 | V16: 0 | W16: 5 | X16: 5 | Z16: A+ | AA16: =IF(Z16="O",100,IF(Z16="A+",90,IF(Z16="A",80,IF(Z16="B+",70,IF(Z16="B",60,IF(Z16="C",55,IF(Z16="P",50,IF(Z16="F",39)))))))) -> 90
A17: 8 | B17: =+B16+1 -> 5191421008 | C17: 2 | D17: 2 | E17: 2 | F17: 2 | G17: 0 | H17: 5 | I17: 4 | J17: 5 | K17: 5 | N17: 2 | O17: 1 | P17: 0 | Q17: 2 | R17: 1 | S17: 2 | T17: 1 | U17: 5 | V17: 4 | W17: 0 | Z17: F | AA17: =IF(Z17="O",100,IF(Z17="A+",90,IF(Z17="A",80,IF(Z17="B+",70,IF(Z17="B",60,IF(Z17="C",55,IF(Z17="P",50,IF(Z17="F",39)))))))) -> 39
A18: 9 | B18: =+B17+1 -> 5191421009 | C18: 2 | D18: 2 | E18: 2 | F18: 2 | G18: 0 | H18: 5 | I18: 5 | L18: 8 | N18: 2 | O18: 2 | P18: 0 | Q18: 1 | R18: 2 | S18: 5 | T18: 5 | U18: 2 | W18: 2 | Z18: A | AA18: =IF(Z18="O",100,IF(Z18="A+",90,IF(Z18="A",80,IF(Z18="B+",70,IF(Z18="B",60,IF(Z18="C",55,IF(Z18="P",50,IF(Z18="F",39)))))))) -> 80
A19: 10 | B19: =+B18+1 -> 5191421010 | C19: 2 | D19: 2 | E19: 2 | F19: 2 | G19: 2 | H19: 5 | I19: 3 | J19: 4 | K19: 5 | N19: 2 | O19: 2 | P19: 1 | Q19: 2 | R19: 2 | S19: 5 | T19: 5 | U19: 5 | Z19: B | AA19: =IF(Z19="O",100,IF(Z19="A+",90,IF(Z19="A",80,IF(Z19="B+",70,IF(Z19="B",60,IF(Z19="C",55,IF(Z19="P",50,IF(Z19="F",39)))))))) -> 60
A20: 11 | B20: =+B19+1 -> 5191421011 | C20: 2 | D20: 2 | E20: 2 | F20: 2 | G20: 2 | H20: 5 | I20: 4 | J20: 2 | K20: 3 | N20: 2 | O20: 2 | P20: 2 | Q20: 2 | R20: 2 | S20: 5 | T20: 5 | U20: 3 | V20: 4 | Z20: A | AA20: =IF(Z20="O",100,IF(Z20="A+",90,IF(Z20="A",80,IF(Z20="B+",70,IF(Z20="B",60,IF(Z20="C",55,IF(Z20="P",50,IF(Z20="F",39)))))))) -> 80
A21: 12 | B21: =+B20+1 -> 5191421012 | C21: 0 | D21: 2 | E21: 2 | F21: 1 | H21: 3 | I21: 3 | J21: 5 | K21: 2 | N21: 0 | O21: 2 | P21: 0 | Q21: 0 | R21: 0 | S21: 0 | T21: 0 | U21: 0 | Z21: F | AA21: =IF(Z21="O",100,IF(Z21="A+",90,IF(Z21="A",80,IF(Z21="B+",70,IF(Z21="B",60,IF(Z21="C",55,IF(Z21="P",50,IF(Z21="F",39)))))))) -> 39
A22: 13 | B22: =+B21+1 -> 5191421013 | C22: 2 | D22: 2 | E22: 2 | F22: 2 | G22: 2 | H22: 5 | I22: 5 | L22: 10 | N22: 2 | O22: 2 | P22: 2 | Q22: 2 | R22: 2 | S22: 5 | T22: 5 | U22: 5 | V22: 5 | Z22: A | AA22: =IF(Z22="O",100,IF(Z22="A+",90,IF(Z22="A",80,IF(Z22="B+",70,IF(Z22="B",60,IF(Z22="C",55,IF(Z22="P",50,IF(Z22="F",39)))))))) -> 80
A23: 14 | B23: =+B22+1 -> 5191421014 | C23: 2 | D23: 2 | E23: 2 | F23: 2 | G23: 2 | H23: 5 | I23: 5 | J23: 5 | K23: 5 | N23: 1 | O23: 1 | P23: 1 | Q23: 1 | R23: 1 | S23: 5 | T23: 5 | U23: 5 | V23: 5 | Z23: A | AA23: =IF(Z23="O",100,IF(Z23="A+",90,IF(Z23="A",80,IF(Z23="B+",70,IF(Z23="B",60,IF(Z23="C",55,IF(Z23="P",50,IF(Z23="F",39)))))))) -> 80
A24: 15 | B24: =+B23+1 -> 5191421015 | C24: 2 | D24: 2 | E24: 2 | F24: 2 | G24: 2 | H24: 3 | I24: 2 | J24: 2 | K24: 4 | N24: 2 | O24: 1 | P24: 0 | Q24: 0 | R24: 1 | S24: 1 | T24: 0 | V24: 0 | Z24: F | AA24: =IF(Z24="O",100,IF(Z24="A+",90,IF(Z24="A",80,IF(Z24="B+",70,IF(Z24="B",60,IF(Z24="C",55,IF(Z24="P",50,IF(Z24="F",39)))))))) -> 39
A25: 16 | B25: =+B24+1 -> 5191421016 | C25: 2 | D25: 2 | E25: 0 | F25: 0 | G25: 0 | H25: 5 | I25: 3 | J25: 5 | N25: 2 | O25: 1 | P25: 0 | Q25: 2 | R25: 2 | S25: 0 | T25: 4 | V25: 1 | Z25: C | AA25: =IF(Z25="O",100,IF(Z25="A+",90,IF(Z25="A",80,IF(Z25="B+",70,IF(Z25="B",60,IF(Z25="C",55,IF(Z25="P",50,IF(Z25="F",39)))))))) -> 55
A26: 17 | B26: =+B25+1 -> 5191421017 | C26: 1 | D26: 2 | E26: 2 | H26: 5 | I26: 5 | J26: 5 | K26: 3 | N26: 2 | O26: 0 | P26: 0 | Q26: 0 | R26: 0 | S26: 2 | T26: 0 | V26: 0 | Z26: C | AA26: =IF(Z26="O",100,IF(Z26="A+",90,IF(Z26="A",80,IF(Z26="B+",70,IF(Z26="B",60,IF(Z26="C",55,IF(Z26="P",50,IF(Z26="F",39)))))))) -> 55
A27: 18 | B27: =+B26+1 -> 5191421018 | C27: 2 | D27: 2 | E27: 2 | H27: 5 | I27: 3 | J27: 2 | N27: 2 | O27: 0 | P27: 0 | Q27: 2 | R27: 0 | S27: 0 | T27: 0 | U27: 5 | V27: 0 | Z27: F | AA27: =IF(Z27="O",100,IF(Z27="A+",90,IF(Z27="A",80,IF(Z27="B+",70,IF(Z27="B",60,IF(Z27="C",55,IF(Z27="P",50,IF(Z27="F",39)))))))) -> 39
A28: 19 | B28: =+B27+1 -> 5191421019 | C28: 2 | D28: 2 | E28: 2 | F28: 2 | G28: 2 | J28: 5 | K28: 5 | L28: 10 | N28: 2 | O28: 2 | P28: 2 | Q28: 2 | R28: 2 | S28: 5 | T28: 5 | U28: 5 | V28: 5 | Z28: A+ | AA28: =IF(Z28="O",100,IF(Z28="A+",90,IF(Z28="A",80,IF(Z28="B+",70,IF(Z28="B",60,IF(Z28="C",55,IF(Z28="P",50,IF(Z28="F",39)))))))) -> 90
A29: 20 | B29: =+B28+1 -> 5191421020 | C29: 2 | D29: 2 | E29: 2 | F29: 2 | G29: 2 | J29: 5 | K29: 5 | L29: 10 | N29: 2 | O29: 2 | P29: 2 | Q29: 2 | R29: 2 | S29: 5 | T29: 5 | U29: 5 | V29: 5 | Z29: A | AA29: =IF(Z29="O",100,IF(Z29="A+",90,IF(Z29="A",80,IF(Z29="B+",70,IF(Z29="B",60,IF(Z29="C",55,IF(Z29="P",50,IF(Z29="F",39)))))))) -> 80
A30: 21 | B30: =+B29+1 -> 5191421021 | C30: 2 | D30: 1 | E30: 0 | F30: 2 | G30: 2 | H30: 5 | I30: 5 | L30: 10 | N30: 2 | O30: 1 | P30: 1 | Q30: 2 | R30: 2 | S30: 4 | T30: 0 | U30: 1 | V30: 0 | W30: 5 | Z30: B | AA30: =IF(Z30="O",100,IF(Z30="A+",90,IF(Z30="A",80,IF(Z30="B+",70,IF(Z30="B",60,IF(Z30="C",55,IF(Z30="P",50,IF(Z30="F",39)))))))) -> 60
A31: 22 | B31: =+B30+1 -> 5191421022 | C31: 2 | D31: 2 | E31: 2 | F31: 2 | H31: 5 | I31: 5 | J31: 3 | N31: 2 | O31: 1 | P31: 0 | Q31: 2 | R31: 2 | S31: 4 | T31: 0 | U31: 0 | V31: 4 | Z31: C | AA31: =IF(Z31="O",100,IF(Z31="A+",90,IF(Z31="A",80,IF(Z31="B+",70,IF(Z31="B",60,IF(Z31="C",55,IF(Z31="P",50,IF(Z31="F",39)))))))) -> 55
A32: 23 | B32: =+B31+1 -> 5191421023 | C32: 2 | D32: 2 | E32: 2 | F32: 2 | G32: 0 | H32: 5 | I32: 5 | J32: 5 | N32: 2 | O32: 2 | P32: 0 | Q32: 2 | R32: 1 | S32: 5 | T32: 5 | U32: 5 | V32: 0 | Z32: C | AA32: =IF(Z32="O",100,IF(Z32="A+",90,IF(Z32="A",80,IF(Z32="B+",70,IF(Z32="B",60,IF(Z32="C",55,IF(Z32="P",50,IF(Z32="F",39)))))))) -> 55
A33: 24 | B33: =+B32+1 -> 5191421024 | C33: 2 | D33: 2 | E33: 2 | F33: 2 | G33: 2 | H33: 5 | I33: 5 | L33: 10 | N33: 2 | O33: 2 | P33: 0 | Q33: 0 | R33: 0 | S33: 4 | T33: 2 | U33: 5 | V33: 3 | Z33: B | AA33: =IF(Z33="O",100,IF(Z33="A+",90,IF(Z33="A",80,IF(Z33="B+",70,IF(Z33="B",60,IF(Z33="C",55,IF(Z33="P",50,IF(Z33="F",39)))))))) -> 60
A34: 25 | B34: =+B33+1 -> 5191421025 | C34: 1 | D34: 2 | E34: 2 | F34: 2 | G34: 2 | J34: 5 | K34: 5 | L34: 10 | N34: 2 | O34: 2 | P34: 2 | Q34: 2 | R34: 2 | S34: 5 | T34: 5 | U34: 5 | V34: 5 | W34: 5 | X34: 5 | Z34: A+ | AA34: =IF(Z34="O",100,IF(Z34="A+",90,IF(Z34="A",80,IF(Z34="B+",70,IF(Z34="B",60,IF(Z34="C",55,IF(Z34="P",50,IF(Z34="F",39)))))))) -> 90
A35: 26 | B35: =+B34+1 -> 5191421026 | C35: 2 | D35: 2 | E35: 2 | F35: 2 | G35: 2 | J35: 5 | K35: 5 | L35: 10 | N35: 2 | O35: 2 | P35: 2 | Q35: 2 | R35: 2 | S35: 5 | T35: 5 | U35: 3 | V35: 3 | Z35: B+ | AA35: =IF(Z35="O",100,IF(Z35="A+",90,IF(Z35="A",80,IF(Z35="B+",70,IF(Z35="B",60,IF(Z35="C",55,IF(Z35="P",50,IF(Z35="F",39)))))))) -> 70
A36: 27 | B36: =+B35+1 -> 5191421027 | N36: 2 | O36: 2 | P36: 2 | Q36: 2 | R36: 2 | S36: 5 | T36: 5 | U36: 3 | V36: 3 | Z36: A | AA36: =IF(Z36="O",100,IF(Z36="A+",90,IF(Z36="A",80,IF(Z36="B+",70,IF(Z36="B",60,IF(Z36="C",55,IF(Z36="P",50,IF(Z36="F",39)))))))) -> 80
A37: 28 | B37: =+B36+1 -> 5191421028 | C37: 2 | D37: 2 | E37: 2 | F37: 2 | G37: 0 | H37: 5 | I37: 5 | L37: 8 | N37: 2 | O37: 2 | P37: 2 | Q37: 2 | R37: 2 | S37: 5 | T37: 5 | U37: 5 | V37: 4 | Z37: A+ | AA37: =IF(Z37="O",100,IF(Z37="A+",90,IF(Z37="A",80,IF(Z37="B+",70,IF(Z37="B",60,IF(Z37="C",55,IF(Z37="P",50,IF(Z37="F",39)))))))) -> 90
A38: 29 | B38: =+B37+1 -> 5191421029 | C38: 1 | D38: 2 | E38: 2 | F38: 1 | G38: 2 | H38: 3 | I38: 3 | J38: 2 | K38: 3 | N38: 2 | O38: 1 | P38: 0 | Q38: 2 | R38: 1 | S38: 5 | T38: 2 | U38: 3 | V38: 3 | Z38: C | AA38: =IF(Z38="O",100,IF(Z38="A+",90,IF(Z38="A",80,IF(Z38="B+",70,IF(Z38="B",60,IF(Z38="C",55,IF(Z38="P",50,IF(Z38="F",39)))))))) -> 55
A39: 30 | B39: =+B38+1 -> 5191421030 | C39: 2 | D39: 2 | H39: 5 | I39: 5 | J39: 3 | N39: 2 | O39: 1 | P39: 0 | Q39: 0 | R39: 2 | S39: 0 | T39: 2 | Z39: F | AA39: =IF(Z39="O",100,IF(Z39="A+",90,IF(Z39="A",80,IF(Z39="B+",70,IF(Z39="B",60,IF(Z39="C",55,IF(Z39="P",50,IF(Z39="F",39)))))))) -> 39
A40: 31 | B40: =+B39+1 -> 5191421031 | C40: 2 | D40: 2 | E40: 2 | F40: 2 | G40: 2 | H40: 4 | I40: 5 | J40: 4 | N40: 2 | O40: 2 | P40: 2 | Q40: 2 | R40: 2 | S40: 3 | T40: 0 | Z40: B+ | AA40: =IF(Z40="O",100,IF(Z40="A+",90,IF(Z40="A",80,IF(Z40="B+",70,IF(Z40="B",60,IF(Z40="C",55,IF(Z40="P",50,IF(Z40="F",39)))))))) -> 70
A41: 32 | B41: =+B40+1 -> 5191421032 | C41: 2 | D41: 0 | E41: 2 | F41: 0 | G41: 0 | H41: 5 | I41: 5 | J41: 3 | N41: 2 | O41: 1 | P41: 0 | Q41: 2 | R41: 0 | S41: 0 | T41: 0 | U41: 4 | V41: 4 | W41: 3 | Z41: F | AA41: =IF(Z41="O",100,IF(Z41="A+",90,IF(Z41="A",80,IF(Z41="B+",70,IF(Z41="B",60,IF(Z41="C",55,IF(Z41="P",50,IF(Z41="F",39)))))))) -> 39
...

Sheet PHY 
B1: Subject: | C1: Physics | G1: Faculty: | H1: Dr.D. Santhosh Kumar | P1: Acd Year: | Q1: 2019-2020
B3: Year and Semester: | C3: 1st Yr I Semester | G3: Mid I/II: | H3: ECE
C4: I Mid | N4: TOTAL MARKS SCOURED | O4: II MID | Z4: TOTAL MARKS SCOURED
B5: Register Number | C5: Question No.1 | H5: Question No 2 | J5: Question No 3 | L5: Question No 4 | O5: Question No.1 | T5: Question No 2 | V5: Question No 3 | X5: Question No 4 | AB5: University Grade | AC5: Marks Obtained
C6: a | D6: b | E6: c | F6: d | G6: e | H6: a | I6: b | J6: a | K6: b | L6: a | M6: b | O6: a | P6: b | Q6: c | R6: d | S6: e | T6: a | U6: b | V6: a | W6: b | X6: a | Y6: b
B7: Matching CO | C7: CO1 | D7: CO2 | E7: CO 2 | F7: CO 1 | G7: CO 3 | H7: CO 1 | I7: CO 1 | J7: CO 1 | K7: CO 2 | L7: CO 1 | M7: CO 3 | O7: CO 3 | P7: CO 4 | Q7: CO 4 | R7: CO 5 | S7: CO 2 | T7: CO 2 | U7: CO 3 | V7: CO 3 | W7: CO 4 | X7: CO 5 | Y7: CO 5
A8: Sl.No. | B8: Maximum Marks | C8: 2 | D8: 2 | E8: 2 | F8: 2 | G8: 2 | H8: 5 | I8: 5 | J8: 5 | K8: 5 | L8: 5 | M8: 5 | N8: 30 | O8: 2 | P8: 2 | Q8: 2 | R8: 2 | S8: 2 | T8: 5 | U8: 5 | V8: 5 | W8: 5 | X8: 5 | Y8: 5 | Z8: 30
A9: 1 | B9: 5191421001 | C9: 2 | E9: 1 | H9: 5 | L9: 5 | N9: =M9+L9+K9+J9+I9+H9+G9+F9+E9+D9+C9 -> 13 | O9: 2 | P9: 1 | Q9: 1 | R9: 1 | T9: 5 | V9: 4 | W9: 3 | Z9: =Y9+X9+W9+V9+U9+T9+S9+R9+Q9+P9+O9 -> 17 | AB9: B | AC9: =IF(AB9="O",100,IF(AB9="A+",95,IF(AB9="A",90,IF(AB9="B+",85,IF(AB9="B",80,IF(AB9="C",70,IF(AB9="D",60,IF(AB9="E",50,IF(AB9="P",49,IF(AB9="F",39)))))))))) -> 80
A10: 2 | B10: 5191421002 | C10: 2 | D10: 1 | F10: 2 | H10: 5 | I10: 5 | L10: 4 | M10: 2 | N10: =M10+L10+K10+J10+I10+H10+G10+F10+E10+D10+C10 -> 21 | O10: 2 | P10: 2 | Q10: 2 | R10: 2 | S10: 2 | T10: 5 | X10: 5 | Z10: =Y10+X10+W10+V10+U10+T10+S10+R10+Q10+P10+O10 -> 20 | AB10: B+ | AC10: =IF(AB10="O",100,IF(AB10="A+",95,IF(AB10="A",90,IF(AB10="B+",85,IF(AB10="B",80,IF(AB10="C",70,IF(AB10="D",60,IF(AB10="E",50,IF(AB10="P",49,IF(AB10="F",39)))))))))) -> 85
A11: 3 | B11: 5191421003 | C11: 2 | D11: 2 | E11: 2 | F11: 2 | G11: 2 | H11: 5 | I11: 5 | L11: 5 | M11: 5 | N11: =M11+L11+K11+J11+I11+H11+G11+F11+E11+D11+C11 -> 30 | O11: 2 | P11: 2 | Q11: 2 | R11: 2 | S11: 2 | V11: 5 | W11: 5 | X11: 5 | Y11: 5 | Z11: =Y11+X11+W11+V11+U11+T11+S11+R11+Q11+P11+O11 -> 30 | AB11: A+ | AC11: =IF(AB11="O",100,IF(AB11="A+",95,IF(AB11="A",90,IF(AB11="B+",85,IF(AB11="B",80,IF(AB11="C",70,IF(AB11="D",60,IF(AB11="E",50,IF(AB11="P",49,IF(AB11="F",39)))))))))) -> 95
A12: 4 | B12: 5191421004 | C12: 2 | D12: 2 | F12: 2 | H12: 4 | K12: 4 | N12: =M12+L12+K12+J12+I12+H12+G12+F12+E12+D12+C12 -> 14 | O12: 1 | P12: 2 | Q12: 1 | R12: 1 | S12: 2 | T12: 3 | W12: 3 | Z12: =Y12+X12+W12+V12+U12+T12+S12+R12+Q12+P12+O12 -> 13 | AB12: C | AC12: =IF(AB12="O",100,IF(AB12="A+",95,IF(AB12="A",90,IF(AB12="B+",85,IF(AB12="B",80,IF(AB12="C",70,IF(AB12="D",60,IF(AB12="E",50,IF(AB12="P",49,IF(AB12="F",39)))))))))) -> 70
A13: 5 | B13: 5191421005 | C13: 2 | D13: 2 | F13: 1 | G13: 2 | H13: 5 | J13: 5 | N13: =M13+L13+K13+J13+I13+H13+G13+F13+E13+D13+C13 -> 17 | O13: 2 | P13: 2 | Q13: 2 | R13: 1 | S13: 2 | T13: 5 | X13: 0 | Y13: 5 | Z13: =Y13+X13+W13+V13+U13+T13+S13+R13+Q13+P13+O13 -> 19 | AB13: B+ | AC13: =IF(AB13="O",100,IF(AB13="A+",95,IF(AB13="A",90,IF(AB13="B+",85,IF(AB13="B",80,IF(AB13="C",70,IF(AB13="D",60,IF(AB13="E",50,IF(AB13="P",49,IF(AB13="F",39)))))))))) -> 85
A14: 6 | B14: 5191421006 | C14: 2 | E14: 2 | F14: 2 | G14: 2 | K14: 5 | L14: 5 | M14: 5 | N14: =M14+L14+K14+J14+I14+H14+G14+F14+E14+D14+C14 -> 23 | O14: 2 | P14: 2 | Q14: 2 | R14: 2 | S14: 2 | T14: 5 | X14: 5 | Y14: 5 | Z14: =Y14+X14+W14+V14+U14+T14+S14+R14+Q14+P14+O14 -> 25 | AB14: A | AC14: =IF(AB14="O",100,IF(AB14="A+",95,IF(AB14="A",90,IF(AB14="B+",85,IF(AB14="B",80,IF(AB14="C",70,IF(AB14="D",60,IF(AB14="E",50,IF(AB14="P",49,IF(AB14="F",39)))))))))) -> 90
A15: 7 | B15: 5191421007 | C15: 2 | E15: 2 | G15: 2 | H15: 5 | I15: 4 | L15: 5 | M15: 5 | N15: =M15+L15+K15+J15+I15+H15+G15+F15+E15+D15+C15 -> 25 | O15: 1 | P15: 2 | Q15: 2 | R15: 2 | S15: 1 | V15: 5 | W15: 5 | Y15: 5 | Z15: =Y15+X15+W15+V15+U15+T15+S15+R15+Q15+P15+O15 -> 23 | AB15: A+ | AC15: =IF(AB15="O",100,IF(AB15="A+",95,IF(AB15="A",90,IF(AB15="B+",85,IF(AB15="B",80,IF(AB15="C",70,IF(AB15="D",60,IF(AB15="E",50,IF(AB15="P",49,IF(AB15="F",39)))))))))) -> 95
A16: 8 | B16: 5191421008 | C16: 2 | D16: 2 | F16: 2 | H16: 5 | I16: 2 | L16: 5 | M16: 4 | N16: =M16+L16+K16+J16+I16+H16+G16+F16+E16+D16+C16 -> 22 | O16: 1 | P16: 2 | Q16: 2 | R16: 2 | S16: 1 | T16: 5 | U16: 1 | X16: 3 | Y16: 4 | Z16: =Y16+X16+W16+V16+U16+T16+S16+R16+Q16+P16+O16 -> 21 | AB16: C | AC16: =IF(AB16="O",100,IF(AB16="A+",95,IF(AB16="A",90,IF(AB16="B+",85,IF(AB16="B",80,IF(AB16="C",70,IF(AB16="D",60,IF(AB16="E",50,IF(AB16="P",49,IF(AB16="F",39)))))))))) -> 70
A17: 9 | B17: 5191421009 | C17: 2 | E17: 2 | H17: 5 | I17: 5 | L17: 5 | M17: 5 | N17: =M17+L17+K17+J17+I17+H17+G17+F17+E17+D17+C17 -> 24 | O17: 2 | P17: 1 | R17: 2 | S17: 1 | T17: 5 | U17: 1 | X17: 1 | Z17: =Y17+X17+W17+V17+U17+T17+S17+R17+Q17+P17+O17 -> 13 | AB17: B+ | AC17: =IF(AB17="O",100,IF(AB17="A+",95,IF(AB17="A",90,IF(AB17="B+",85,IF(AB17="B",80,IF(AB17="C",70,IF(AB17="D",60,IF(AB17="E",50,IF(AB17="P",49,IF(AB17="F",39)))))))))) -> 85
A18: 10 | B18: 5191421010 | C18: 2 | H18: 5 | I18: 4 | L18: 5 | N18: =M18+L18+K18+J18+I18+H18+G18+F18+E18+D18+C18 -> 16 | O18: 2 | P18: 2 | Q18: 2 | R18: 1 | S18: 2 | T18: 5 | W18: 3 | Z18: =Y18+X18+W18+V18+U18+T18+S18+R18+Q18+P18+O18 -> 17 | AB18: C | AC18: =IF(AB18="O",100,IF(AB18="A+",95,IF(AB18="A",90,IF(AB18="B+",85,IF(AB18="B",80,IF(AB18="C",70,IF(AB18="D",60,IF(AB18="E",50,IF(AB18="P",49,IF(AB18="F",39)))))))))) -> 70
A19: 11 | B19: 5191421011 | C19: 2 | E19: 2 | G19: 2 | J19: 5 | K19: 5 | L19: 5 | M19: 5 | N19: =M19+L19+K19+J19+I19+H19+G19+F19+E19+D19+C19 -> 26 | O19: 2 | P19: 2 | Q19: 2 | R19: 2 | S19: 2 | V19: 1 | W19: 5 | X19: 5 | Y19: 5 | Z19: =Y19+X19+W19+V19+U19+T19+S19+R19+Q19+P19+O19 -> 26 | AB19: A+ | AC19: =IF(AB19="O",100,IF(AB19="A+",95,IF(AB19="A",90,IF(AB19="B+",85,IF(AB19="B",80,IF(AB19="C",70,IF(AB19="D",60,IF(AB19="E",50,IF(AB19="P",49,IF(AB19="F",39)))))))))) -> 95
A20: 12 | B20: 5191421012 | H20: 4 | L20: 4 | N20: =M20+L20+K20+J20+I20+H20+G20+F20+E20+D20+C20 -> 8 | O20: 1 | P20: 1 | Q20: 1 | R20: 1 | T20: 4 | U20: 1 | W20: 5 | Z20: =Y20+X20+W20+V20+U20+T20+S20+R20+Q20+P20+O20 -> 14 | AB20: F | AC20: =IF(AB20="O",100,IF(AB20="A+",95,IF(AB20="A",90,IF(AB20="B+",85,IF(AB20="B",80,IF(AB20="C",70,IF(AB20="D",60,IF(AB20="E",50,IF(AB20="P",49,IF(AB20="F",39)))))))))) -> 39
A21: 13 | B21: 5191421013 | C21: 2 | E21: 2 | G21: 2 | H21: 5 | I21: 5 | L21: 5 | M21: 5 | N21: =M21+L21+K21+J21+I21+H21+G21+F21+E21+D21+C21 -> 26 | O21: 2 | P21: 2 | Q21: 2 | R21: 2 | S21: 2 | W21: 5 | X21: 5 | Y21: 5 | Z21: =Y21+X21+W21+V21+U21+T21+S21+R21+Q21+P21+O21 -> 25 | AB21: A | AC21: =IF(AB21="O",100,IF(AB21="A+",95,IF(AB21="A",90,IF(AB21="B+",85,IF(AB21="B",80,IF(AB21="C",70,IF(AB21="D",60,IF(AB21="E",50,IF(AB21="P",49,IF(AB21="F",39)))))))))) -> 90
A22: 14 | B22: 5191421014 | C22: 2 | E22: 2 | G22: 2 | H22: 5 | L22: 5 | M22: 5 | N22: =M22+L22+K22+J22+I22+H22+G22+F22+E22+D22+C22 -> 21 | O22: 2 | P22: 2 | Q22: 2 | R22: 1 | T22: 5 | Z22: =Y22+X22+W22+V22+U22+T22+S22+R22+Q22+P22+O22 -> 12 | AB22: B+ | AC22: =IF(AB22="O",100,IF(AB22="A+",95,IF(AB22="A",90,IF(AB22="B+",85,IF(AB22="B",80,IF(AB22="C",70,IF(AB22="D",60,IF(AB22="E",50,IF(AB22="P",49,IF(AB22="F",39)))))))))) -> 85
A23: 15 | B23: 5191421015 | H23: 2 | I23: 5 | K23: 5 | N23: =M23+L23+K23+J23+I23+H23+G23+F23+E23+D23+C23 -> 12 | O23: 2 | P23: 2 | Q23: 2 | R23: 2 | S23: 2 | V23: 5 | W23: 3 | X23: 4 | Y23: 5 | Z23: =Y23+X23+W23+V23+U23+T23+S23+R23+Q23+P23+O23 -> 27 | AB23: C | AC23: =IF(AB23="O",100,IF(AB23="A+",95,IF(AB23="A",90,IF(AB23="B+",85,IF(AB23="B",80,IF(AB23="C",70,IF(AB23="D",60,IF(AB23="E",50,IF(AB23="P",49,IF(AB23="F",39)))))))))) -> 70
A24: 16 | B24: 5191421016 | C24: 2 | E24: 1 | H24: 4 | I24: 3 | J24: 4 | K24: 5 | N24: =M24+L24+K24+J24+I24+H24+G24+F24+E24+D24+C24 -> 19 | O24: 2 | P24: 2 | Q24: 2 | R24: 2 | S24: 1 | T24: 5 | V24: 5 | W24: 5 | Z24: =Y24+X24+W24+V24+U24+T24+S24+R24+Q24+P24+O24 -> 24 | AB24: F | AC24: =IF(AB24="O",100,IF(AB24="A+",95,IF(AB24="A",90,IF(AB24="B+",85,IF(AB24="B",80,IF(AB24="C",70,IF(AB24="D",60,IF(AB24="E",50,IF(AB24="P",49,IF(AB24="F",39)))))))))) -> 39
A25: 17 | B25: 5191421017 | C25: 2 | D25: 2 | E25: 2 | H25: 4 | L25: 5 | M25: 2 | N25: =M25+L25+K25+J25+I25+H25+G25+F25+E25+D25+C25 -> 17 | O25: 1 | P25: 2 | Q25: 2 | R25: 2 | S25: 2 | T25: 5 | W25: 4 | Z25: =Y25+X25+W25+V25+U25+T25+S25+R25+Q25+P25+O25 -> 18 | AB25: B+ | AC25: =IF(AB25="O",100,IF(AB25="A+",95,IF(AB25="A",90,IF(AB25="B+",85,IF(AB25="B",80,IF(AB25="C",70,IF(AB25="D",60,IF(AB25="E",50,IF(AB25="P",49,IF(AB25="F",39)))))))))) -> 85
A26: 18 | B26: 5191421018 | E26: 2 | N26: =M26+L26+K26+J26+I26+H26+G26+F26+E26+D26+C26 -> 2 | O26: 2 | Q26: 1 | R26: 2 | S26: 1 | V26: 3 | W26: 1 | Z26: =Y26+X26+W26+V26+U26+T26+S26+R26+Q26+P26+O26 -> 10 | AB26: F | AC26: =IF(AB26="O",100,IF(AB26="A+",95,IF(AB26="A",90,IF(AB26="B+",85,IF(AB26="B",80,IF(AB26="C",70,IF(AB26="D",60,IF(AB26="E",50,IF(AB26="P",49,IF(AB26="F",39)))))))))) -> 39
A27: 19 | B27: 5191421019 | C27: 2 | D27: 2 | E27: 2 | G27: 2 | H27: 5 | I27: 5 | L27: 5 | N27: =M27+L27+K27+J27+I27+H27+G27+F27+E27+D27+C27 -> 23 | O27: 2 | P27: 2 | Q27: 2 | R27: 2 | S27: 2 | T27: 5 | V27: 5 | W27: 5 | Z27: =Y27+X27+W27+V27+U27+T27+S27+R27+Q27+P27+O27 -> 25 | AB27: A | AC27: =IF(AB27="O",100,IF(AB27="A+",95,IF(AB27="A",90,IF(AB27="B+",85,IF(AB27="B",80,IF(AB27="C",70,IF(AB27="D",60,IF(AB27="E",50,IF(AB27="P",49,IF(AB27="F",39)))))))))) -> 90
A28: 20 | B28: 5191421020 | C28: 2 | D28: 2 | E28: 2 | F28: 2 | G28: 2 | H28: 5 | I28: 5 | J28: 5 | K28: 5 | N28: =M28+L28+K28+J28+I28+H28+G28+F28+E28+D28+C28 -> 30 | O28: 1 | P28: 1 | Q28: 1 | R28: 2 | S28: 2 | V28: 5 | W28: 4 | X28: 5 | Y28: 4 | Z28: =Y28+X28+W28+V28+U28+T28+S28+R28+Q28+P28+O28 -> 25 | AB28: A+ | AC28: =IF(AB28="O",100,IF(AB28="A+",95,IF(AB28="A",90,IF(AB28="B+",85,IF(AB28="B",80,IF(AB28="C",70,IF(AB28="D",60,IF(AB28="E",50,IF(AB28="P",49,IF(AB28="F",39)))))))))) -> 95
A29: 21 | B29: 5191421021 | H29: 5 | I29: 2 | L29: 5 | M29: 5 | N29: =M29+L29+K29+J29+I29+H29+G29+F29+E29+D29+C29 -> 17 | O29: 2 | V29: 4 | W29: 1 | X29: 4 | Z29: =Y29+X29+W29+V29+U29+T29+S29+R29+Q29+P29+O29 -> 11 | AB29: F | AC29: =IF(AB29="O",100,IF(AB29="A+",95,IF(AB29="A",90,IF(AB29="B+",85,IF(AB29="B",80,IF(AB29="C",70,IF(AB29="D",60,IF(AB29="E",50,IF(AB29="P",49,IF(AB29="F",39)))))))))) -> 39
A30: 22 | B30: 5191421022 | C30: 2 | D30: 2 | E30: 2 | H30: 5 | J30: 4 | K30: 4 | N30: =M30+L30+K30+J30+I30+H30+G30+F30+E30+D30+C30 -> 19 | O30: 1 | P30: 2 | Q30: 1 | S30: 1 | T30: 4 | Z30: =Y30+X30+W30+V30+U30+T30+S30+R30+Q30+P30+O30 -> 9 | AB30: B+ | AC30: =IF(AB30="O",100,IF(AB30="A+",95,IF(AB30="A",90,IF(AB30="B+",85,IF(AB30="B",80,IF(AB30="C",70,IF(AB30="D",60,IF(AB30="E",50,IF(AB30="P",49,IF(AB30="F",39)))))))))) -> 85
A31: 23 | B31: 5191421023 | C31: 2 | F31: 1 | K31: 2 | L31: 5 | N31: =M31+L31+K31+J31+I31+H31+G31+F31+E31+D31+C31 -> 10 | O31: 2 | P31: 2 | Q31: 2 | R31: 2 | T31: 5 | W31: 5 | Z31: =Y31+X31+W31+V31+U31+T31+S31+R31+Q31+P31+O31 -> 18 | AB31: F | AC31: =IF(AB31="O",100,IF(AB31="A+",95,IF(AB31="A",90,IF(AB31="B+",85,IF(AB31="B",80,IF(AB31="C",70,IF(AB31="D",60,IF(AB31="E",50,IF(AB31="P",49,IF(AB31="F",39)))))))))) -> 39
A32: 24 | B32: 5191421024 | C32: 2 | H32: 3 | L32: 4 | N32: =M32+L32+K32+J32+I32+H32+G32+F32+E32+D32+C32 -> 9 | O32: 2 | P32: 2 | Q32: 2 | R32: 2 | T32: 2 | V32: 4 | W32: 2 | Z32: =Y32+X32+W32+V32+U32+T32+S32+R32+Q32+P32+O32 -> 16 | AB32: C | AC32: =IF(AB32="O",100,IF(AB32="A+",95,IF(AB32="A",90,IF(AB32="B+",85,IF(AB32="B",80,IF(AB32="C",70,IF(AB32="D",60,IF(AB32="E",50,IF(AB32="P",49,IF(AB32="F",39)))))))))) -> 70
A33: 25 | B33: 5191421025 | C33: 2 | D33: 2 | E33: 2 | F33: 2 | G33: 2 | H33: 5 | I33: 5 | L33: 5 | M33: 5 | N33: =M33+L33+K33+J33+I33+H33+G33+F33+E33+D33+C33 -> 30 | O33: 2 | P33: 2 | Q33: 2 | R33: 2 | S33: 2 | T33: 5 | U33: 5 | X33: 5 | Y33: 5 | Z33: =Y33+X33+W33+V33+U33+T33+S33+R33+Q33+P33+O33 -> 30 | AB33: O | AC33: =IF(AB33="O",100,IF(AB33="A+",95,IF(AB33="A",90,IF(AB33="B+",85,IF(AB33="B",80,IF(AB33="C",70,IF(AB33="D",60,IF(AB33="E",50,IF(AB33="P",49,IF(AB33="F",39)))))))))) -> 100
A34: 26 | B34: 5191421026 | C34: 2 | D34: 2 | E34: 2 | F34: 2 | H34: 5 | I34: 3 | L34: 5 | N34: =M34+L34+K34+J34+I34+H34+G34+F34+E34+D34+C34 -> 21 | O34: 2 | P34: 2 | Q34: 2 | R34: 2 | S34: 2 | T34: 5 | V34: 5 | W34: 4 | Z34: =Y34+X34+W34+V34+U34+T34+S34+R34+Q34+P34+O34 -> 24 | AB34: B+ | AC34: =IF(AB34="O",100,IF(AB34="A+",95,IF(AB34="A",90,IF(AB34="B+",85,IF(AB34="B",80,IF(AB34="C",70,IF(AB34="D",60,IF(AB34="E",50,IF(AB34="P",49,IF(AB34="F",39)))))))))) -> 85
A35: 27 | B35: 5191421027 | N35: =M35+L35+K35+J35+I35+H35+G35+F35+E35+D35+C35 -> 0 | O35: 2 | P35: 2 | Q35: 2 | R35: 2 | S35: 2 | T35: 5 | X35: 4 | Y35: 5 | Z35: =Y35+X35+W35+V35+U35+T35+S35+R35+Q35+P35+O35 -> 24 | AB35: B | AC35: =IF(AB35="O",100,IF(AB35="A+",95,IF(AB35="A",90,IF(AB35="B+",85,IF(AB35="B",80,IF(AB35="C",70,IF(AB35="D",60,IF(AB35="E",50,IF(AB35="P",49,IF(AB35="F",39)))))))))) -> 80
A36: 28 | B36: 5191421028 | C36: 2 | E36: 2 | F36: 2 | G36: 2 | H36: 5 | I36: 5 | J36: 5 | K36: 5 | N36: =M36+L36+K36+J36+I36+H36+G36+F36+E36+D36+C36 -> 28 | O36: 2 | P36: 2 | Q36: 2 | R36: 2 | S36: 2 | V36: 5 | W36: 5 | X36: 5 | Y36: 5 | Z36: =Y36+X36+W36+V36+U36+T36+S36+R36+Q36+P36+O36 -> 30 | AB36: A+ | AC36: =IF(AB36="O",100,IF(AB36="A+",95,IF(AB36="A",90,IF(AB36="B+",85,IF(AB36="B",80,IF(AB36="C",70,IF(AB36="D",60,IF(AB36="E",50,IF(AB36="P",49,IF(AB36="F",39)))))))))) -> 95
A37: 29 | B37: 5191421029 | C37: 2 | F37: 2 | G37: 2 | H37: 5 | I37: 2 | L37: 5 | M37: 5 | N37: =M37+L37+K37+J37+I37+H37+G37+F37+E37+D37+C37 -> 23 | O37: 2 | P37: 2 | Q37: 2 | R37: 2 | X37: 5 | Z37: =Y37+X37+W37+V37+U37+T37+S37+R37+Q37+P37+O37 -> 13 | AB37: C | AC37: =IF(AB37="O",100,IF(AB37="A+",95,IF(AB37="A",90,IF(AB37="B+",85,IF(AB37="B",80,IF(AB37="C",70,IF(AB37="D",60,IF(AB37="E",50,IF(AB37="P",49,IF(AB37="F",39)))))))))) -> 70
A38: 30 | B38: 5191421030 | K38: 2 | L38: 4 | N38: =M38+L38+K38+J38+I38+H38+G38+F38+E38+D38+C38 -> 6 | O38: 1 | P38: 2 | Q38: 2 | R38: 2 | S38: 1 | V38: 2 | Z38: =Y38+X38+W38+V38+U38+T38+S38+R38+Q38+P38+O38 -> 10 | AB38: F | AC38: =IF(AB38="O",100,IF(AB38="A+",95,IF(AB38="A",90,IF(AB38="B+",85,IF(AB38="B",80,IF(AB38="C",70,IF(AB38="D",60,IF(AB38="E",50,IF(AB38="P",49,IF(AB38="F",39)))))))))) -> 39
A39: 31 | B39: 5191421031 | C39: 2 | E39: 1 | H39: 5 | J39: 5 | K39: 5 | N39: =M39+L39+K39+J39+I39+H39+G39+F39+E39+D39+C39 -> 18 | O39: 2 | P39: 2 | Q39: 1 | R39: 1 | S39: 2 | T39: 5 | X39: 3 | Z39: =Y39+X39+W39+V39+U39+T39+S39+R39+Q39+P39+O39 -> 16 | AB39: B+ | AC39: =IF(AB39="O",100,IF(AB39="A+",95,IF(AB39="A",90,IF(AB39="B+",85,IF(AB39="B",80,IF(AB39="C",70,IF(AB39="D",60,IF(AB39="E",50,IF(AB39="P",49,IF(AB39="F",39)))))))))) -> 85
A40: 32 | B40: 5191421032 | L40: 3 | M40: 1 | N40: =M40+L40+K40+J40+I40+H40+G40+F40+E40+D40+C40 -> 4 | O40: 2 | P40: 2 | Q40: 2 | R40: 2 | S40: 2 | T40: 1 | U40: 1 | V40: 1 | W40: 1 | Z40: =Y40+X40+W40+V40+U40+T40+S40+R40+Q40+P40+O40 -> 14 | AB40: F | AC40: =IF(AB40="O",100,IF(AB40="A+",95,IF(AB40="A",90,IF(AB40="B+",85,IF(AB40="B",80,IF(AB40="C",70,IF(AB40="D",60,IF(AB40="E",50,IF(AB40="P",49,IF(AB40="F",39)))))))))) -> 39
A41: 33 | B41: 5191421033 | C41: 2 | D41: 2 | E41: 2 | F41: 2 | G41: 2 | H41: 5 | I41: 5 | L41: 5 | M41: 5 | N41: =M41+L41+K41+J41+I41+H41+G41+F41+E41+D41+C41 -> 30 | O41: 1 | P41: 2 | Q41: 2 | R41: 2 | S41: 2 | V41: 5 | W41: 4 | X41: 5 | Y41: 5 | Z41: =Y41+X41+W41+V41+U41+T41+S41+R41+Q41+P41+O41 -> 28 | AB41: A+ | AC41: =IF(AB41="O",100,IF(AB41="A+",95,IF(AB41="A",90,IF(AB41="B+",85,IF(AB41="B",80,IF(AB41="C",70,IF(AB41="D",60,IF(AB41="E",50,IF(AB41="P",49,IF(AB41="F",39)))))))))) -> 95
...

Sheet EG
A3: Subject: | C3: EG | H3: AY: | J3: 2019-20
A4: Faculty: | C4: CHG | H4: Batch: | J4: 2019-2023
B5: Year and Semester: | C5: I Yr I Semester | H5: Branch: | J5: ECE
C6: MID I | K6: MID II
B7: Register Number | C7: Question No.1 | H7: Q2 | I7: Q3 | J7: Q4 | K7: Question No.1 | P7: Q2 | Q7: Q3 | R7: Q4 | T7: University Grade | U7: Marks Obtained
C8: a | D8: b | E8: c | F8: d | G8: e | K8: a | L8: b | M8: c | N8: d | O8: e
B9: Matching CO | C9: 1 | D9: 2 | E9: 2 | F9: 1 | G9: 3 | H9: 1 | I9: 3 | J9: 2 | K9: 1 | L9: 1 | M9: 1 | N9: 4 | O9: 1 | P9: 2 | Q9: 3 | R9: 4
A10: Sl.No. | B10: Maximum Marks | C10: 2 | D10: 2 | E10: 2 | F10: 2 | G10: 2 | H10: 10 | I10: 10 | J10: 10 | K10: 2 | L10: 2 | M10: 2 | N10: 2 | O10: 2 | P10: 10 | Q10: 10 | R10: 10 | U10: 70
A11: 1 | B11: 5191421001 | C11: 2 | D11: 2 | E11: 2 | F11: 2 | G11: 2 | H11: 10 | I11: 10 | J11: 10 | K11: 1 | L11: 1 | M11: 2 | N11: 1 | O11: 1 | P11: 4 | R11: 10 | T11: C | U11: =IF(T11="F",0,IF(T11="O",100,IF(T11="A+",90,IF(T11="A",80,IF(T11="B+",70,IF(T11="B",60,IF(T11="C",55,IF(T11="P",50)))))))) -> 55
A12: 2 | B12: =+B11+1 -> 5191421002 | C12: 0 | D12: 2 | E12: 2 | F12: 0 | G12: 1 | H12: 3 | I12: 4 | J12: 9 | K12: 2 | L12: 1 | M12: 2 | N12: 1 | O12: 2 | Q12: 5 | R12: 8 | T12: C | U12: =IF(T12="F",0,IF(T12="O",100,IF(T12="A+",90,IF(T12="A",80,IF(T12="B+",70,IF(T12="B",60,IF(T12="C",55,IF(T12="P",50)))))))) -> 55
A13: 3 | B13: =+B12+1 -> 5191421003 | C13: 0 | D13: 1 | E13: 2 | F13: 0 | G13: 2 | H13: 2 | I13: 8 | J13: 9 | K13: 2 | L13: 1 | M13: 2 | N13: 1 | O13: 2 | Q13: 9 | R13: 10 | T13: A | U13: =IF(T13="F",0,IF(T13="O",100,IF(T13="A+",90,IF(T13="A",80,IF(T13="B+",70,IF(T13="B",60,IF(T13="C",55,IF(T13="P",50)))))))) -> 80
A14: 4 | B14: =+B13+1 -> 5191421004 | C14: 2 | D14: 2 | E14: 2 | F14: 0 | G14: 2 | H14: 7 | I14: 7 | J14: 6 | K14: 2 | L14: 1 | M14: 2 | N14: 1 | O14: 1 | Q14: 7 | T14: F | U14: =IF(T14="F",0,IF(T14="O",100,IF(T14="A+",90,IF(T14="A",80,IF(T14="B+",70,IF(T14="B",60,IF(T14="C",55,IF(T14="P",50)))))))) -> 0
A15: 5 | B15: =+B14+1 -> 5191421005 | C15: 1 | D15: 2 | E15: 2 | F15: 0 | G15: 2 | H15: 2 | J15: 3 | K15: 2 | L15: 1 | M15: 2 | N15: 1 | O15: 1 | P15: 2 | Q15: 3 | T15: F | U15: =IF(T15="F",0,IF(T15="O",100,IF(T15="A+",90,IF(T15="A",80,IF(T15="B+",70,IF(T15="B",60,IF(T15="C",55,IF(T15="P",50)))))))) -> 0
A16: 6 | B16: =+B15+1 -> 5191421006 | C16: 2 | D16: 1 | E16: 0 | F16: 0 | G16: 2 | H16: 4 | I16: 0 | K16: 1 | L16: 1 | M16: 2 | N16: 2 | O16: 1 | Q16: 2 | T16: B+ | U16: =IF(T16="F",0,IF(T16="O",100,IF(T16="A+",90,IF(T16="A",80,IF(T16="B+",70,IF(T16="B",60,IF(T16="C",55,IF(T16="P",50)))))))) -> 70
A17: 7 | B17: =+B16+1 -> 5191421007 | C17: 1 | D17: 1 | F17: 0 | G17: 2 | H17: 4 | K17: 2 | L17: 0 | M17: 2 | N17: 1 | O17: 1 | P17: 3 | Q17: 4 | T17: C | U17: =IF(T17="F",0,IF(T17="O",100,IF(T17="A+",90,IF(T17="A",80,IF(T17="B+",70,IF(T17="B",60,IF(T17="C",55,IF(T17="P",50)))))))) -> 55
A18: 8 | B18: =+B17+1 -> 5191421008 | C18: 2 | D18: 0 | E18: 2 | F18: 0 | G18: 2 | H18: 7 | I18: 0 | J18: 1 | K18: 2 | L18: 1 | M18: 2 | N18: 2 | O18: 1 | P18: 3 | Q18: 6 | T18: C | U18: =IF(T18="F",0,IF(T18="O",100,IF(T18="A+",90,IF(T18="A",80,IF(T18="B+",70,IF(T18="B",60,IF(T18="C",55,IF(T18="P",50)))))))) -> 55
A19: 9 | B19: =+B18+1 -> 5191421009 | C19: 2 | G19: 2 | H19: 3 | I19: 5 | J19: 1 | K19: 2 | L19: 1 | M19: 2 | N19: 2 | O19: 1 | P19: 3 | Q19: 6 | T19: B+ | U19: =IF(T19="F",0,IF(T19="O",100,IF(T19="A+",90,IF(T19="A",80,IF(T19="B+",70,IF(T19="B",60,IF(T19="C",55,IF(T19="P",50)))))))) -> 70
A20: 10 | B20: =+B19+1 -> 5191421010 | C20: 1 | D20: 1 | E20: 2 | F20: 0 | G20: 1 | H20: 3 | J20: 0 | K20: 2 | L20: 1 | M20: 2 | N20: 1 | O20: 1 | P20: 2 | Q20: 3 | T20: B+ | U20: =IF(T20="F",0,IF(T20="O",100,IF(T20="A+",90,IF(T20="A",80,IF(T20="B+",70,IF(T20="B",60,IF(T20="C",55,IF(T20="P",50)))))))) -> 70
A21: 11 | B21: =+B20+1 -> 5191421011 | C21: 1 | D21: 1 | E21: 1 | F21: 1 | G21: 1 | K21: 2 | L21: 1 | M21: 2 | N21: 1 | O21: 2 | P21: 4 | R21: 3 | T21: B+ | U21: =IF(T21="F",0,IF(T21="O",100,IF(T21="A+",90,IF(T21="A",80,IF(T21="B+",70,IF(T21="B",60,IF(T21="C",55,IF(T21="P",50)))))))) -> 70
A22: 12 | B22: =+B21+1 -> 5191421012 | C22: 1 | D22: 2 | E22: 2 | F22: 1 | G22: 1 | H22: 7 | J22: 8 | K22: 2 | L22: 1 | M22: 2 | N22: 1 | O22: 2 | Q22: 2 | R22: 1 | T22: C | U22: =IF(T22="F",0,IF(T22="O",100,IF(T22="A+",90,IF(T22="A",80,IF(T22="B+",70,IF(T22="B",60,IF(T22="C",55,IF(T22="P",50)))))))) -> 55
A23: 13 | B23: =+B22+1 -> 5191421013 | C23: 2 | D23: 1 | E23: 2 | G23: 1 | H23: 3 | J23: 3 | K23: 2 | L23: 1 | M23: 2 | N23: 1 | O23: 2 | Q23: 3 | T23: A | U23: =IF(T23="F",0,IF(T23="O",100,IF(T23="A+",90,IF(T23="A",80,IF(T23="B+",70,IF(T23="B",60,IF(T23="C",55,IF(T23="P",50)))))))) -> 80
A24: 14 | B24: =+B23+1 -> 5191421014 | C24: 2 | D24: 2 | E24: 2 | F24: 0 | G24: 1 | H24: 3 | J24: 6 | K24: 2 | L24: 1 | M24: 2 | N24: 1 | O24: 1 | Q24: 2 | R24: 1 | T24: B | U24: =IF(T24="F",0,IF(T24="O",100,IF(T24="A+",90,IF(T24="A",80,IF(T24="B+",70,IF(T24="B",60,IF(T24="C",55,IF(T24="P",50)))))))) -> 60
A25: 15 | B25: =+B24+1 -> 5191421015 | C25: 1 | D25: 2 | E25: 1 | G25: 2 | H25: 3 | J25: 4 | K25: 2 | L25: 1 | M25: 2 | N25: 1 | O25: 1 | Q25: 1 | R25: 1 | T25: C | U25: =IF(T25="F",0,IF(T25="O",100,IF(T25="A+",90,IF(T25="A",80,IF(T25="B+",70,IF(T25="B",60,IF(T25="C",55,IF(T25="P",50)))))))) -> 55
A26: 16 | B26: =+B25+1 -> 5191421016 | C26: 1 | D26: 2 | G26: 2 | H26: 5 | J26: 1 | K26: 2 | L26: 1 | M26: 2 | N26: 2 | O26: 2 | Q26: 3 | T26: P | U26: =IF(T26="F",0,IF(T26="O",100,IF(T26="A+",90,IF(T26="A",80,IF(T26="B+",70,IF(T26="B",60,IF(T26="C",55,IF(T26="P",50)))))))) -> 50
A27: 17 | B27: =+B26+1 -> 5191421017 | C27: 2 | D27: 2 | E27: 2 | G27: 2 | H27: 5 | J27: 4 | K27: 2 | L27: 1 | M27: 2 | N27: 2 | O27: 2 | Q27: 10 | R27: 3 | T27: B+ | U27: =IF(T27="F",0,IF(T27="O",100,IF(T27="A+",90,IF(T27="A",80,IF(T27="B+",70,IF(T27="B",60,IF(T27="C",55,IF(T27="P",50)))))))) -> 70
A28: 18 | B28: =+B27+1 -> 5191421018 | C28: 2 | D28: 2 | E28: 2 | H28: 6 | J28: 7 | K28: 2 | L28: 1 | M28: 2 | N28: 2 | O28: 2 | P28: 4 | Q28: 8 | T28: F | U28: =IF(T28="F",0,IF(T28="O",100,IF(T28="A+",90,IF(T28="A",80,IF(T28="B+",70,IF(T28="B",60,IF(T28="C",55,IF(T28="P",50)))))))) -> 0
A29: 19 | B29: =+B28+1 -> 5191421019 | C29: 2 | D29: 2 | E29: 2 | F29: 0 | G29: 1 | H29: 6 | J29: 4 | K29: 2 | L29: 1 | M29: 2 | N29: 2 | O29: 2 | P29: 4 | T29: B+ | U29: =IF(T29="F",0,IF(T29="O",100,IF(T29="A+",90,IF(T29="A",80,IF(T29="B+",70,IF(T29="B",60,IF(T29="C",55,IF(T29="P",50)))))))) -> 70
A30: 20 | B30: =+B29+1 -> 5191421020 | C30: 2 | D30: 2 | E30: 2 | G30: 1 | H30: 6 | K30: 2 | L30: 1 | M30: 2 | N30: 2 | O30: 1 | P30: 4 | Q30: 3 | T30: A | U30: =IF(T30="F",0,IF(T30="O",100,IF(T30="A+",90,IF(T30="A",80,IF(T30="B+",70,IF(T30="B",60,IF(T30="C",55,IF(T30="P",50)))))))) -> 80
A31: 21 | B31: =+B30+1 -> 5191421021 | C31: 2 | D31: 2 | E31: 2 | G31: 1 | H31: 5 | K31: 2 | M31: 2 | N31: 1 | O31: 1 | P31: 2 | Q31: 6 | R31: 4 | T31: B+ | U31: =IF(T31="F",0,IF(T31="O",100,IF(T31="A+",90,IF(T31="A",80,IF(T31="B+",70,IF(T31="B",60,IF(T31="C",55,IF(T31="P",50)))))))) -> 70
A32: 22 | B32: =+B31+1 -> 5191421022 | C32: 1 | D32: 2 | E32: 2 | F32: 0 | G32: 2 | I32: 4 | J32: 4 | K32: 2 | M32: 2 | N32: 0 | O32: 1 | P32: 2 | Q32: 5 | T32: P | U32: =IF(T32="F",0,IF(T32="O",100,IF(T32="A+",90,IF(T32="A",80,IF(T32="B+",70,IF(T32="B",60,IF(T32="C",55,IF(T32="P",50)))))))) -> 50
A33: 23 | B33: =+B32+1 -> 5191421023 | C33: 1 | D33: 2 | E33: 2 | G33: 2 | H33: 6 | I33: 3 | K33: 2 | M33: 2 | N33: 1 | O33: 2 | Q33: 3 | T33: B+ | U33: =IF(T33="F",0,IF(T33="O",100,IF(T33="A+",90,IF(T33="A",80,IF(T33="B+",70,IF(T33="B",60,IF(T33="C",55,IF(T33="P",50)))))))) -> 70
A34: 24 | B34: =+B33+1 -> 5191421024 | C34: 2 | D34: 2 | E34: 2 | F34: 0 | G34: 2 | H34: 4 | J34: 4 | K34: 2 | L34: 0 | M34: 1 | N34: 1 | O34: 2 | P34: 0 | Q34: 3 | T34: P | U34: =IF(T34="F",0,IF(T34="O",100,IF(T34="A+",90,IF(T34="A",80,IF(T34="B+",70,IF(T34="B",60,IF(T34="C",55,IF(T34="P",50)))))))) -> 50
A35: 25 | B35: =+B34+1 -> 5191421025 | C35: 1 | D35: 1 | E35: 2 | G35: 2 | H35: 4 | I35: 7 | J35: 2 | K35: 2 | M35: 1 | N35: 1 | O35: 2 | Q35: 3 | R35: 3 | T35: A+ | U35: =IF(T35="F",0,IF(T35="O",100,IF(T35="A+",90,IF(T35="A",80,IF(T35="B+",70,IF(T35="B",60,IF(T35="C",55,IF(T35="P",50)))))))) -> 90
A36: 26 | B36: =+B35+1 -> 5191421026 | C36: 1 | D36: 1 | E36: 2 | F36: 2 | G36: 0 | H36: 6 | J36: 8 | K36: 2 | L36: 1 | M36: 2 | N36: 1 | O36: 1 | Q36: 3 | R36: 0 | T36: B+ | U36: =IF(T36="F",0,IF(T36="O",100,IF(T36="A+",90,IF(T36="A",80,IF(T36="B+",70,IF(T36="B",60,IF(T36="C",55,IF(T36="P",50)))))))) -> 70
